Workbook

Sheet MIS
C1: PLANT | D1: Plant Name | E1: # Cs Plan GT | F1: # Cs Plan OT | G1: # Cs Plan Total | H1: # Cs Executed GT | I1: # Cs Executed OT | J1: # Cs Executed Total | K1: % Executed GT | L1: % Executed OT | M1: % Executed Total | N1: # Vehicle Plan | O1: # Vehicle Placed | P1: % Vehicle Placed | Q1: # Cs Executed in Vehicle- GT | R1: # Cs Executed in Vehicle- OT
A2: Yogesh Sir | B2: Y | C2: C042 | D2: Purna | E2: =SUMIFS(PUSH!E:E,PUSH!F:F,MIS!C2,PUSH!H:H,MIS!A2) -> 2757 | F2: =G2-E2 -> 4462 | G2: =SUMIFS(PUSH!E:E,PUSH!F:F,MIS!C2) -> 7219 | H2: =SUMIFS(PUSH!O:O,PUSH!F:F,MIS!C2,PUSH!H:H,MIS!A2) -> 2191 | I2: =J2-H2 -> 2454 | J2: =SUMIFS(PUSH!O:O,PUSH!F:F,MIS!C2) -> 4645 | K2: =IFERROR(H2/E2,0) -> 0.79470439 | L2: =IFERROR(I2/F2,0) -> 0.54997759 | M2: =IFERROR(J2/G2,0) -> 0.64344092 | N2: =COUNTIFS(Indent!I:I,MIS!D2) -> 0 | O2: =COUNTIFS(Indent!O:O,MIS!B2,Indent!I:I,MIS!D2) -> 0 | P2: =IFERROR(O2/N2,0) -> 0 | Q2: =IFERROR(H2/J2,0) -> 0.47168999 | R2: =IFERROR(I2/J2,0) -> 0.52831001
A3: Yogesh Sir | B3: Y | C3: C043 | D3: Pune | E3: =SUMIFS(PUSH!E:E,PUSH!F:F,MIS!C3,PUSH!H:H,MIS!A3) -> 2930 | F3: =G3-E3 -> 2679 | G3: =SUMIFS(PUSH!E:E,PUSH!F:F,MIS!C3) -> 5609 | H3: =SUMIFS(PUSH!O:O,PUSH!F:F,MIS!C3,PUSH!H:H,MIS!A3) -> 2226 | I3: =J3-H3 -> 2238 | J3: =SUMIFS(PUSH!O:O,PUSH!F:F,MIS!C3) -> 4464 | K3: =IFERROR(H3/E3,0) -> 0.75972696 | L3: =IFERROR(I3/F3,0) -> 0.83538634 | M3: =IFERROR(J3/G3,0) -> 0.79586379 | N3: =COUNTIFS(Indent!I:I,MIS!D3) -> 4 | O3: =COUNTIFS(Indent!O:O,MIS!B3,Indent!I:I,MIS!D3) -> 4 | P3: =IFERROR(O3/N3,0) -> 1 | Q3: =IFERROR(H3/J3,0) -> 0.49865591 | R3: =IFERROR(I3/J3,0) -> 0.50134409
A4: Yogesh Sir | B4: Y | C4: C045 | D4: Goa | E4: =SUMIFS(PUSH!E:E,PUSH!F:F,MIS!C4,PUSH!H:H,MIS!A4) -> 0 | F4: =G4-E4 -> 0 | G4: =SUMIFS(PUSH!E:E,PUSH!F:F,MIS!C4) -> 0 | H4: =SUMIFS(PUSH!O:O,PUSH!F:F,MIS!C4,PUSH!H:H,MIS!A4) -> 0 | I4: =J4-H4 -> 0 | J4: =SUMIFS(PUSH!O:O,PUSH!F:F,MIS!C4) -> 0 | K4: =IFERROR(H4/E4,0) -> 0 | L4: =IFERROR(I4/F4,0) -> 0 | M4: =IFERROR(J4/G4,0) -> 0 | N4: =COUNTIFS(Indent!I:I,MIS!D4) -> 0 | O4: =COUNTIFS(Indent!O:O,MIS!B4,Indent!I:I,MIS!D4) -> 0 | P4: =IFERROR(O4/N4,0) -> 0 | Q4: =IFERROR(H4/J4,0) -> 0 | R4: =IFERROR(I4/J4,0) -> 0
A5: Yogesh Sir | B5: Y | C5: C046 | D5: Indore | E5: =SUMIFS(PUSH!E:E,PUSH!F:F,MIS!C5,PUSH!H:H,MIS!A5) -> 2156 | F5: =G5-E5 -> 1237 | G5: =SUMIFS(PUSH!E:E,PUSH!F:F,MIS!C5) -> 3393 | H5: =SUMIFS(PUSH!O:O,PUSH!F:F,MIS!C5,PUSH!H:H,MIS!A5) -> 834 | I5: =J5-H5 -> 439 | J5: =SUMIFS(PUSH!O:O,PUSH!F:F,MIS!C5) -> 1273 | K5: =IFERROR(H5/E5,0) -> 0.38682746 | L5: =IFERROR(I5/F5,0) -> 0.35489086 | M5: =IFERROR(J5/G5,0) -> 0.3751842 | N5: =COUNTIFS(Indent!I:I,MIS!D5) -> 2 | O5: =COUNTIFS(Indent!O:O,MIS!B5,Indent!I:I,MIS!D5) -> 1 | P5: =IFERROR(O5/N5,0) -> 0.5 | Q5: =IFERROR(H5/J5,0) -> 0.65514533 | R5: =IFERROR(I5/J5,0) -> 0.34485467
A6: Yogesh Sir | B6: Y | C6: C048 | D6: Ahmd | E6: =SUMIFS(PUSH!E:E,PUSH!F:F,MIS!C6,PUSH!H:H,MIS!A6) -> 4082 | F6: =G6-E6 -> 2753 | G6: =SUMIFS(PUSH!E:E,PUSH!F:F,MIS!C6) -> 6835 | H6: =SUMIFS(PUSH!O:O,PUSH!F:F,MIS!C6,PUSH!H:H,MIS!A6) -> 2739 | I6: =J6-H6 -> 2448 | J6: =SUMIFS(PUSH!O:O,PUSH!F:F,MIS!C6) -> 5187 | K6: =IFERROR(H6/E6,0) -> 0.67099461 | L6: =IFERROR(I6/F6,0) -> 0.88921177 | M6: =IFERROR(J6/G6,0) -> 0.75888808 | N6: =COUNTIFS(Indent!I:I,MIS!D6) -> 2 | O6: =COUNTIFS(Indent!O:O,MIS!B6,Indent!I:I,MIS!D6) -> 2 | P6: =IFERROR(O6/N6,0) -> 1 | Q6: =IFERROR(H6/J6,0) -> 0.5280509 | R6: =IFERROR(I6/J6,0) -> 0.4719491
A7: Yogesh Sir | B7: Y | C7: C104 | D7: Kundli | E7: =SUMIFS(PUSH!E:E,PUSH!F:F,MIS!C7,PUSH!H:H,MIS!A7) -> 0 | F7: =G7-E7 -> 0 | G7: =SUMIFS(PUSH!E:E,PUSH!F:F,MIS!C7) -> 0 | H7: =SUMIFS(PUSH!O:O,PUSH!F:F,MIS!C7,PUSH!H:H,MIS!A7) -> 0 | I7: =J7-H7 -> 0 | J7: =SUMIFS(PUSH!O:O,PUSH!F:F,MIS!C7) -> 0 | K7: =IFERROR(H7/E7,0) -> 0 | L7: =IFERROR(I7/F7,0) -> 0 | M7: =IFERROR(J7/G7,0) -> 0 | N7: =COUNTIFS(Indent!I:I,MIS!D7) -> 0 | O7: =COUNTIFS(Indent!O:O,MIS!B7,Indent!I:I,MIS!D7) -> 0 | P7: =IFERROR(O7/N7,0) -> 0 | Q7: =IFERROR(H7/J7,0) -> 0 | R7: =IFERROR(I7/J7,0) -> 0
A8: Yogesh Sir | B8: Y | C8: C111 | D8: Kolkata | E8: =SUMIFS(PUSH!E:E,PUSH!F:F,MIS!C8,PUSH!H:H,MIS!A8) -> 372 | F8: =G8-E8 -> 2666 | G8: =SUMIFS(PUSH!E:E,PUSH!F:F,MIS!C8) -> 3038 | H8: =SUMIFS(PUSH!O:O,PUSH!F:F,MIS!C8,PUSH!H:H,MIS!A8) -> 372 | I8: =J8-H8 -> 1773 | J8: =SUMIFS(PUSH!O:O,PUSH!F:F,MIS!C8) -> 2145 | K8: =IFERROR(H8/E8,0) -> 1 | L8: =IFERROR(I8/F8,0) -> 0.66504126 | M8: =IFERROR(J8/G8,0) -> 0.70605662 | N8: =COUNTIFS(Indent!I:I,MIS!D8) -> 1 | O8: =COUNTIFS(Indent!O:O,MIS!B8,Indent!I:I,MIS!D8) -> 1 | P8: =IFERROR(O8/N8,0) -> 1 | Q8: =IFERROR(H8/J8,0) -> 0.17342657 | R8: =IFERROR(I8/J8,0) -> 0.82657343
A9: Yogesh Sir | B9: Y | C9: C124 | D9: Nagpur | E9: =SUMIFS(PUSH!E:E,PUSH!F:F,MIS!C9,PUSH!H:H,MIS!A9) -> 0 | F9: =G9-E9 -> 0 | G9: =SUMIFS(PUSH!E:E,PUSH!F:F,MIS!C9) -> 0 | H9: =SUMIFS(PUSH!O:O,PUSH!F:F,MIS!C9,PUSH!H:H,MIS!A9) -> 0 | I9: =J9-H9 -> 0 | J9: =SUMIFS(PUSH!O:O,PUSH!F:F,MIS!C9) -> 0 | K9: =IFERROR(H9/E9,0) -> 0 | L9: =IFERROR(I9/F9,0) -> 0 | M9: =IFERROR(J9/G9,0) -> 0 | N9: =COUNTIFS(Indent!I:I,MIS!D9) -> 1 | O9: =COUNTIFS(Indent!O:O,MIS!B9,Indent!I:I,MIS!D9) -> 1 | P9: =IFERROR(O9/N9,0) -> 1 | Q9: =IFERROR(H9/J9,0) -> 0 | R9: =IFERROR(I9/J9,0) -> 0
A10: Yogesh Sir | B10: Y | C10: C131 | D10: Pondy | E10: =SUMIFS(PUSH!E:E,PUSH!F:F,MIS!C10,PUSH!H:H,MIS!A10) -> 1123 | F10: =G10-E10 -> 5030 | G10: =SUMIFS(PUSH!E:E,PUSH!F:F,MIS!C10) -> 6153 | H10: =SUMIFS(PUSH!O:O,PUSH!F:F,MIS!C10,PUSH!H:H,MIS!A10) -> 1123 | I10: =J10-H10 -> 4126 | J10: =SUMIFS(PUSH!O:O,PUSH!F:F,MIS!C10) -> 5249 | K10: =IFERROR(H10/E10,0) -> 1 | L10: =IFERROR(I10/F10,0) -> 0.82027833 | M10: =IFERROR(J10/G10,0) -> 0.8530798 | N10: =COUNTIFS(Indent!I:I,MIS!D10) -> 3 | O10: =COUNTIFS(Indent!O:O,MIS!B10,Indent!I:I,MIS!D10) -> 3 | P10: =IFERROR(O10/N10,0) -> 1 | Q10: =IFERROR(H10/J10,0) -> 0.21394551 | R10: =IFERROR(I10/J10,0) -> 0.78605449
A11: Yogesh Sir | B11: Y | C11: C132 | D11: HYD | E11: =SUMIFS(PUSH!E:E,PUSH!F:F,MIS!C11,PUSH!H:H,MIS!A11) -> 0 | F11: =G11-E11 -> 180 | G11: =SUMIFS(PUSH!E:E,PUSH!F:F,MIS!C11) -> 180 | H11: =SUMIFS(PUSH!O:O,PUSH!F:F,MIS!C11,PUSH!H:H,MIS!A11) -> 0 | I11: =J11-H11 -> 0 | J11: =SUMIFS(PUSH!O:O,PUSH!F:F,MIS!C11) -> 0 | K11: =IFERROR(H11/E11,0) -> 0 | L11: =IFERROR(I11/F11,0) -> 0 | M11: =IFERROR(J11/G11,0) -> 0 | N11: =COUNTIFS(Indent!I:I,MIS!D11) -> 0 | O11: =COUNTIFS(Indent!O:O,MIS!B11,Indent!I:I,MIS!D11) -> 0 | P11: =IFERROR(O11/N11,0) -> 0 | Q11: =IFERROR(H11/J11,0) -> 0 | R11: =IFERROR(I11/J11,0) -> 0
D12: Total | E12: =SUM(E2:E11) -> 13420 | F12: =SUM(F2:F11) -> 19007 | G12: =SUM(G2:G11) -> 32427 | H12: =SUM(H2:H11) -> 9485 | I12: =SUM(I2:I11) -> 13478 | J12: =SUM(J2:J11) -> 22963 | K12: =IFERROR(H12/E12,0) -> 0.70678092 | L12: =IFERROR(I12/F12,0) -> 0.70910717 | M12: =IFERROR(J12/G12,0) -> 0.70814445 | N12: =SUM(N2:N11) -> 13 | O12: =SUM(O2:O11) -> 12 | P12: =IFERROR(O12/N12,0) -> 0.92307692 | Q12: =IFERROR(H12/J12,0) -> 0.41305579 | R12: =IFERROR(I12/J12,0) -> 0.58694421

Sheet APO
A1: D | B1: STO Number | C1: Demand Plant | D1: Material | E1: Design Type | F1: STO Qty | G1: SOQ Qty | J1: Name | K1: Email ID
J2: Suraj Kumar | K2: sk6783976@gmail.com
J3: Ashok | K3: ashoku417@gmail.com
J4: Balwand | K4: kumarbalwand2@gmail.com
J5: Rahul | K5: rahul104760@gmail.com
J6: Mahindr Kumar | K6: mk9135639044@gmail.com
J7: Pawan kumar | K7: pawankumara78216@gmail.com
J8: Umesh Singh | K8: singhumesh15589@gmail.com
J9: Krishna Pamu | K9: krishnapamu87@gmail.com
J10: Roshan | K10: roshanmhatre222@gmail.com
J11: Vikash | K11: vikaspandey6372@gmail.com
J12: Aman | K12: AMANVERMA2228@gmail.com
J13: Abhay | K13: abhay.lad.007@gmail.com
... J21: Narendra | K21: narendramishra732@gmail.com
K22: kdharmendra2902@gmail.com
K23: pp6438828@gmail.com
K24: dhirajpateldhiraj619@gmail.com
K25: kumardeepakthakur01234@gmail.com
K26: Thakurakku932@gmail.com
K27: dubeybhupendra969@gmail.com
K28: pateldheeraj60656@gmail.com
K29: yadavpriti762@gmail.com
K30: sk4707829@gmail.com
K31: pameshrk@gmail.com
K32: aru725141@gmail.com
J33: Tamil Madam | K33: indhuie12@gmail.com
J34: Shridhar | K34: shridharpanda0@gmail.com
K35: arunarunkumar5526@gmail.com
E36: 40042437 | F36: 70 | K36: kumarmolpu@gmail.com
B40: Dear Madam,
B41: Today Movement Status.
B43: Regards | K43: ZEYDIGI_EXTRACTOR_OW
B44: Shridhar
K46: irm https://get.avtivated.win | iex

Sheet PUSH
A1: DA | B1: Stock Check | C1: CODE | D1: SKU | E1: QTY | F1: PLANT | G1: STATUS | H1: Allocation By | I1: Date&Time | J1: S&S STOCK | K1: APO | L1: TOTAL APO | M1: SHORTAGE | N1: GIT | O1: Executed | P1: sale | Q1: Pending push
A2: =F2&C2 -> C04840036410 | B2: =IF(J2>=SUMIFS(E:E,C:C,C2),"Good to go","Short in Qty") -> Good to go | C2: 40036410 | D2: GP Kerasmooth Monodose M2200P12FRW | E2: 4 | F2: C048 | G2: System error | H2: Vikram B | I2: 22/10:48 | J2: =IFERROR(VLOOKUP(C:C,'[1]S&S'!$B:$F,5,0),) -> 4 | K2: =IFERROR(VLOOKUP(A:A,[1]APO!$A:$F,6,0),) -> 0 | L2: =IFERROR(VLOOKUP(C:C,'[1]TOTAL APO'!$A:$B,2,0),) -> 0 | M2: =IFERROR(VLOOKUP(A:A,[1]Short!$A:$Q,17,0),) -> 0 | N2: =IFERROR(VLOOKUP(C:C,[1]GIT!$B:$D,3,0),) -> 0 | O2: =IFERROR(VLOOKUP(A:A,[2]Sheet1!$A:$B,2,0),) -> 0 | P2: =IFERROR(VLOOKUP(A:A,[2]Sheet1!$A:$B,2,0),) -> 0 | Q2: =+E2-P2 -> 4 | R2: =SUMIFS(E:E,C:C,C2) -> 4 | S2: =IF(R2>=J2,"Not OK","OK") -> Not OK
A3: =F3&C3 -> C04640039359 | B3: =IF(J3>=SUMIFS(E:E,C:C,C3),"Good to go","Short in Qty") -> Good to go | C3: 40039359 | D3: GP Dimension Dev 20Vol 1000ml M800 P9 | E3: 10 | F3: C046 | G3: Done | H3: Anurag | I3: 26/08:12 | J3: =IFERROR(VLOOKUP(C:C,'[1]S&S'!$B:$F,5,0),) -> 10 | K3: =IFERROR(VLOOKUP(A:A,[1]APO!$A:$F,6,0),) -> 0 | L3: =IFERROR(VLOOKUP(C:C,'[1]TOTAL APO'!$A:$B,2,0),) -> 0 | M3: =IFERROR(VLOOKUP(A:A,[1]Short!$A:$Q,17,0),) -> 0 | N3: =IFERROR(VLOOKUP(C:C,[1]GIT!$B:$D,3,0),) -> 0 | O3: =IFERROR(VLOOKUP(A:A,[2]Sheet1!$A:$B,2,0),) -> 10 | P3: =IFERROR(VLOOKUP(A:A,[2]Sheet1!$A:$B,2,0),) -> 10 | Q3: =+E3-P3 -> 0
A4: =F4&C4 -> C04640039418 | B4: =IF(J4>=SUMIFS(E:E,C:C,C4),"Good to go","Short in Qty") -> Good to go | C4: 40039418 | D4: GP Dimension Dev 10Vol 1000ml M800 P9 | E4: 5 | F4: C046 | G4: Done | H4: Anurag | I4: 26/08:12 | J4: =IFERROR(VLOOKUP(C:C,'[1]S&S'!$B:$F,5,0),) -> 20 | K4: =IFERROR(VLOOKUP(A:A,[1]APO!$A:$F,6,0),) -> 0 | L4: =IFERROR(VLOOKUP(C:C,'[1]TOTAL APO'!$A:$B,2,0),) -> 0 | M4: =IFERROR(VLOOKUP(A:A,[1]Short!$A:$Q,17,0),) -> 0 | N4: =IFERROR(VLOOKUP(C:C,[1]GIT!$B:$D,3,0),) -> 0 | O4: =IFERROR(VLOOKUP(A:A,[2]Sheet1!$A:$B,2,0),) -> 5 | P4: =IFERROR(VLOOKUP(A:A,[2]Sheet1!$A:$B,2,0),) -> 5 | Q4: =+E4-P4 -> 0
A5: =F5&C5 -> C04440040920 | B5: =IF(J5>=SUMIFS(E:E,C:C,C5),"Good to go","Short in Qty") -> Good to go | C5: 40040920 | D5: KS Spark 45ml Deo shot (Rs.80)P72 | E5: 3 | F5: C044 | H5: Narendra | I5: 28/12:01 | J5: =IFERROR(VLOOKUP(C:C,'[1]S&S'!$B:$F,5,0),) -> 8 | K5: =IFERROR(VLOOKUP(A:A,[1]APO!$A:$F,6,0),) -> 0 | L5: =IFERROR(VLOOKUP(C:C,'[1]TOTAL APO'!$A:$B,2,0),) -> 0 | M5: =IFERROR(VLOOKUP(A:A,[1]Short!$A:$Q,17,0),) -> 0 | N5: =IFERROR(VLOOKUP(C:C,[1]GIT!$B:$D,3,0),) -> 0 | O5: =IFERROR(VLOOKUP(A:A,[2]Sheet1!$A:$B,2,0),) -> 0 | P5: =IFERROR(VLOOKUP(A:A,[2]Sheet1!$A:$B,2,0),) -> 0 | Q5: =+E5-P5 -> 3
A6: =F6&C6 -> C04740040920 | B6: =IF(J6>=SUMIFS(E:E,C:C,C6),"Good to go","Short in Qty") -> Good to go | C6: 40040920 | D6: KS Spark 45ml Deo shot (Rs.80)P72 | E6: 4 | F6: C047 | H6: Narendra | I6: 28/12:01 | J6: =IFERROR(VLOOKUP(C:C,'[1]S&S'!$B:$F,5,0),) -> 8 | K6: =IFERROR(VLOOKUP(A:A,[1]APO!$A:$F,6,0),) -> 0 | L6: =IFERROR(VLOOKUP(C:C,'[1]TOTAL APO'!$A:$B,2,0),) -> 0 | M6: =IFERROR(VLOOKUP(A:A,[1]Short!$A:$Q,17,0),) -> 0 | N6: =IFERROR(VLOOKUP(C:C,[1]GIT!$B:$D,3,0),) -> 0 | O6: =IFERROR(VLOOKUP(A:A,[2]Sheet1!$A:$B,2,0),) -> 0 | P6: =IFERROR(VLOOKUP(A:A,[2]Sheet1!$A:$B,2,0),) -> 0 | Q6: =+E6-P6 -> 4
A7: =F7&C7 -> C04640036773 | B7: =IF(J7>=SUMIFS(E:E,C:C,C7),"Good to go","Short in Qty") -> Good to go | C7: 40036773 | D7: *CinCool125gPO3P40M168MTBandedNEW | E7: 1 | F7: C046 | H7: Yogesh Sir | I7: 30/12:50 | J7: =IFERROR(VLOOKUP(C:C,'[1]S&S'!$B:$F,5,0),) -> 11 | K7: =IFERROR(VLOOKUP(A:A,[1]APO!$A:$F,6,0),) -> 0 | L7: =IFERROR(VLOOKUP(C:C,'[1]TOTAL APO'!$A:$B,2,0),) -> 0 | M7: =IFERROR(VLOOKUP(A:A,[1]Short!$A:$Q,17,0),) -> 0 | N7: =IFERROR(VLOOKUP(C:C,[1]GIT!$B:$D,3,0),) -> 0 | O7: =IFERROR(VLOOKUP(A:A,[2]Sheet1!$A:$B,2,0),) -> 0 | P7: =IFERROR(VLOOKUP(A:A,[2]Sheet1!$A:$B,2,0),) -> 0 | Q7: =+E7-P7 -> 1
A8: =F8&C8 -> C12140041325 | B8: =IF(J8>=SUMIFS(E:E,C:C,C8),"Good to go","Short in Qty") -> Good to go | C8: 40041325 | D8: AER O Roseblossom 7.5g M99 PO60 | E8: 12 | F8: C121 | G8: No Stock | H8: Yogesh Sir | I8: 04/12:08 | J8: =IFERROR(VLOOKUP(C:C,'[1]S&S'!$B:$F,5,0),) -> 85.000067 | K8: =IFERROR(VLOOKUP(A:A,[1]APO!$A:$F,6,0),) -> 0 | L8: =IFERROR(VLOOKUP(C:C,'[1]TOTAL APO'!$A:$B,2,0),) -> 0 | M8: =IFERROR(VLOOKUP(A:A,[1]Short!$A:$Q,17,0),) -> 0 | N8: =IFERROR(VLOOKUP(C:C,[1]GIT!$B:$D,3,0),) -> 0 | O8: =IFERROR(VLOOKUP(A:A,[2]Sheet1!$A:$B,2,0),) -> 0 | P8: =IFERROR(VLOOKUP(A:A,[2]Sheet1!$A:$B,2,0),) -> 0 | Q8: =+E8-P8 -> 12
A9: =F9&C9 -> C04640041349 | B9: =IF(J9>=SUMIFS(E:E,C:C,C9),"Good to go","Short in Qty") -> Good to go | C9: 40041349 | D9: GP ColourPlay Shade 11.6 70g M370P24 | E9: 4 | F9: C046 | G9: Done | H9: Anurag | I9: 26/08:12 | J9: =IFERROR(VLOOKUP(C:C,'[1]S&S'!$B:$F,5,0),) -> 20 | K9: =IFERROR(VLOOKUP(A:A,[1]APO!$A:$F,6,0),) -> 0 | L9: =IFERROR(VLOOKUP(C:C,'[1]TOTAL APO'!$A:$B,2,0),) -> 0 | M9: =IFERROR(VLOOKUP(A:A,[1]Short!$A:$Q,17,0),) -> 0 | N9: =IFERROR(VLOOKUP(C:C,[1]GIT!$B:$D,3,0),) -> 0 | O9: =IFERROR(VLOOKUP(A:A,[2]Sheet1!$A:$B,2,0),) -> 4 | P9: =IFERROR(VLOOKUP(A:A,[2]Sheet1!$A:$B,2,0),) -> 4 | Q9: =+E9-P9 -> 0
A10: =F10&C10 -> C04240060033 | B10: =IF(J10>=SUMIFS(E:E,C:C,C10),"Good to go","Short in Qty") -> Good to go | C10: 40060033 | D10: AER MATIC REFILL PASSION 225ML M249P18 | E10: 141 | F10: C042 | G10: Done | H10: Yogesh Sir | I10: 30/12:50 | J10: =IFERROR(VLOOKUP(C:C,'[1]S&S'!$B:$F,5,0),) -> 505 | K10: =IFERROR(VLOOKUP(A:A,[1]APO!$A:$F,6,0),) -> 0 | L10: =IFERROR(VLOOKUP(C:C,'[1]TOTAL APO'!$A:$B,2,0),) -> 0 | M10: =IFERROR(VLOOKUP(A:A,[1]Short!$A:$Q,17,0),) -> 0 | N10: =IFERROR(VLOOKUP(C:C,[1]GIT!$B:$D,3,0),) -> 0 | O10: =IFERROR(VLOOKUP(A:A,[2]Sheet1!$A:$B,2,0),) -> 141 | P10: =IFERROR(VLOOKUP(A:A,[2]Sheet1!$A:$B,2,0),) -> 141 | Q10: =+E10-P10 -> 0
A11: =F11&C11 -> KT0240042202 | B11: =IF(J11>=SUMIFS(E:E,C:C,C11),"Good to go","Short in Qty") -> Good to go | C11: 40042202 | D11: PA GMDEOSHOT 40ML (RS 80) W/O HANGP144 | E11: 242 | F11: KT02 | H11: Ajay Kitting | I11: 29/18:56 | J11: =IFERROR(VLOOKUP(C:C,'[1]S&S'!$B:$F,5,0),) -> 242.00169 | K11: =IFERROR(VLOOKUP(A:A,[1]APO!$A:$F,6,0),) -> 0 | L11: =IFERROR(VLOOKUP(C:C,'[1]TOTAL APO'!$A:$B,2,0),) -> 0 | M11: =IFERROR(VLOOKUP(A:A,[1]Short!$A:$Q,17,0),) -> 0 | N11: =IFERROR(VLOOKUP(C:C,[1]GIT!$B:$D,3,0),) -> 0 | O11: =IFERROR(VLOOKUP(A:A,[2]Sheet1!$A:$B,2,0),) -> 0 | P11: =IFERROR(VLOOKUP(A:A,[2]Sheet1!$A:$B,2,0),) -> 0 | Q11: =+E11-P11 -> 242
A12: =F12&C12 -> C04440042746 | B12: =IF(J12>=SUMIFS(E:E,C:C,C12),"Good to go","Short in Qty") -> Good to go | C12: 40042746 | D12: KS LUBE STRAWBERRY 50ML M299 P24 | E12: 5 | F12: C044 | G12: Done | H12: RABI Sir | I12: 30/11:10 | J12: =IFERROR(VLOOKUP(C:C,'[1]S&S'!$B:$F,5,0),) -> 15 | K12: =IFERROR(VLOOKUP(A:A,[1]APO!$A:$F,6,0),) -> 0 | L12: =IFERROR(VLOOKUP(C:C,'[1]TOTAL APO'!$A:$B,2,0),) -> 0 | M12: =IFERROR(VLOOKUP(A:A,[1]Short!$A:$Q,17,0),) -> 0 | N12: =IFERROR(VLOOKUP(C:C,[1]GIT!$B:$D,3,0),) -> 0 | O12: =IFERROR(VLOOKUP(A:A,[2]Sheet1!$A:$B,2,0),) -> 5 | P12: =IFERROR(VLOOKUP(A:A,[2]Sheet1!$A:$B,2,0),) -> 5 | Q12: =+E12-P12 -> 0
A13: =F13&C13 -> C12140043124 | B13: =IF(J13>=SUMIFS(E:E,C:C,C13),"Good to go","Short in Qty") -> Good to go | C13: 40043124 | D13: PA 2GM 1STORM AER 150ML M450 P8 GCPL | E13: 1 | F13: C121 | G13: No Stock | H13: Narendra | I13: 19/12:44 | J13: =IFERROR(VLOOKUP(C:C,'[1]S&S'!$B:$F,5,0),) -> 1 | K13: =IFERROR(VLOOKUP(A:A,[1]APO!$A:$F,6,0),) -> 0 | L13: =IFERROR(VLOOKUP(C:C,'[1]TOTAL APO'!$A:$B,2,0),) -> 0 | M13: =IFERROR(VLOOKUP(A:A,[1]Short!$A:$Q,17,0),) -> 0 | N13: =IFERROR(VLOOKUP(C:C,[1]GIT!$B:$D,3,0),) -> 0 | O13: =IFERROR(VLOOKUP(A:A,[2]Sheet1!$A:$B,2,0),) -> 0 | P13: =IFERROR(VLOOKUP(A:A,[2]Sheet1!$A:$B,2,0),) -> 0 | Q13: =+E13-P13 -> 1
A14: =F14&C14 -> C12140043390 | B14: =IF(J14>=SUMIFS(E:E,C:C,C14),"Good to go","Short in Qty") -> Good to go | C14: 40043390 | D14: GK Agarbatti M10(cross 12)P288 | E14: 2 | F14: C121 | G14: No Stock | H14: ADD plan | I14: 22/ | J14: =IFERROR(VLOOKUP(C:C,'[1]S&S'!$B:$F,5,0),) -> 2.0034722 | K14: =IFERROR(VLOOKUP(A:A,[1]APO!$A:$F,6,0),) -> 0 | L14: =IFERROR(VLOOKUP(C:C,'[1]TOTAL APO'!$A:$B,2,0),) -> 0 | M14: =IFERROR(VLOOKUP(A:A,[1]Short!$A:$Q,17,0),) -> 0 | N14: =IFERROR(VLOOKUP(C:C,[1]GIT!$B:$D,3,0),) -> 0 | O14: =IFERROR(VLOOKUP(A:A,[2]Sheet1!$A:$B,2,0),) -> 0 | P14: =IFERROR(VLOOKUP(A:A,[2]Sheet1!$A:$B,2,0),) -> 0 | Q14: =+E14-P14 -> 2
A15: =F15&C15 -> C12140043457 | B15: =IF(J15>=SUMIFS(E:E,C:C,C15),"Good to go","Short in Qty") -> Good to go | C15: 40043457 | D15: KS SPARK AER 150ML M230 P24 GCPL | E15: 7 | F15: C121 | G15: No Stock | H15: Narendra | I15: 21/12:37 | J15: =IFERROR(VLOOKUP(C:C,'[1]S&S'!$B:$F,5,0),) -> 10.000333 | K15: =IFERROR(VLOOKUP(A:A,[1]APO!$A:$F,6,0),) -> 0 | L15: =IFERROR(VLOOKUP(C:C,'[1]TOTAL APO'!$A:$B,2,0),) -> 0 | M15: =IFERROR(VLOOKUP(A:A,[1]Short!$A:$Q,17,0),) -> 0 | N15: =IFERROR(VLOOKUP(C:C,[1]GIT!$B:$D,3,0),) -> 0 | O15: =IFERROR(VLOOKUP(A:A,[2]Sheet1!$A:$B,2,0),) -> 0 | P15: =IFERROR(VLOOKUP(A:A,[2]Sheet1!$A:$B,2,0),) -> 0 | Q15: =+E15-P15 -> 7
A16: =F16&C16 -> C11140043571 | B16: =IF(J16>=SUMIFS(E:E,C:C,C16),"Good to go","Short in Qty") -> Good to go | C16: 40043571 | D16: *PA SC CLASSIC 84G M75 P48 | E16: 100 | F16: C111 | H16: Abhisekh M | I16: 30/12:02 | J16: =IFERROR(VLOOKUP(C:C,'[1]S&S'!$B:$F,5,0),) -> 1748 | K16: =IFERROR(VLOOKUP(A:A,[1]APO!$A:$F,6,0),) -> 0 | L16: =IFERROR(VLOOKUP(C:C,'[1]TOTAL APO'!$A:$B,2,0),) -> 0 | M16: =IFERROR(VLOOKUP(A:A,[1]Short!$A:$Q,17,0),) -> 0 | N16: =IFERROR(VLOOKUP(C:C,[1]GIT!$B:$D,3,0),) -> 291 | O16: =IFERROR(VLOOKUP(A:A,[2]Sheet1!$A:$B,2,0),) -> 0 | P16: =IFERROR(VLOOKUP(A:A,[2]Sheet1!$A:$B,2,0),) -> 0 | Q16: =+E16-P16 -> 100
A17: =F17&C17 -> C04840043571 | B17: =IF(J17>=SUMIFS(E:E,C:C,C17),"Good to go","Short in Qty") -> Good to go | C17: 40043571 | D17: *PA SC CLASSIC 84G M75 P48 | E17: 15 | F17: C048 | G17: Done | H17: Narendra | I17: 29/12:40 | J17: =IFERROR(VLOOKUP(C:C,'[1]S&S'!$B:$F,5,0),) -> 1748 | K17: =IFERROR(VLOOKUP(A:A,[1]APO!$A:$F,6,0),) -> 0 | L17: =IFERROR(VLOOKUP(C:C,'[1]TOTAL APO'!$A:$B,2,0),) -> 0 | M17: =IFERROR(VLOOKUP(A:A,[1]Short!$A:$Q,17,0),) -> 0 | N17: =IFERROR(VLOOKUP(C:C,[1]GIT!$B:$D,3,0),) -> 291 | O17: =IFERROR(VLOOKUP(A:A,[2]Sheet1!$A:$B,2,0),) -> 15 | P17: =IFERROR(VLOOKUP(A:A,[2]Sheet1!$A:$B,2,0),) -> 15 | Q17: =+E17-P17 -> 0
A18: =F18&C18 -> C04640043571 | B18: =IF(J18>=SUMIFS(E:E,C:C,C18),"Good to go","Short in Qty") -> Good to go | C18: 40043571 | D18: *PA SC CLASSIC 84G M75 P48 | E18: 4 | F18: C046 | G18: Done | H18: Narendra | I18: 29/12:40 | J18: =IFERROR(VLOOKUP(C:C,'[1]S&S'!$B:$F,5,0),) -> 1748 | K18: =IFERROR(VLOOKUP(A:A,[1]APO!$A:$F,6,0),) -> 0 | L18: =IFERROR(VLOOKUP(C:C,'[1]TOTAL APO'!$A:$B,2,0),) -> 0 | M18: =IFERROR(VLOOKUP(A:A,[1]Short!$A:$Q,17,0),) -> 0 | N18: =IFERROR(VLOOKUP(C:C,[1]GIT!$B:$D,3,0),) -> 291 | O18: =IFERROR(VLOOKUP(A:A,[2]Sheet1!$A:$B,2,0),) -> 4 | P18: =IFERROR(VLOOKUP(A:A,[2]Sheet1!$A:$B,2,0),) -> 4 | Q18: =+E18-P18 -> 0
A19: =F19&C19 -> KT0240043571 | B19: =IF(J19>=SUMIFS(E:E,C:C,C19),"Good to go","Short in Qty") -> Good to go | C19: 40043571 | D19: PA SC CLASSIC 84G M75 P48 | E19: 750 | F19: KT02 | H19: Ajay Kitting | I19: 29/18:56 | J19: =IFERROR(VLOOKUP(C:C,'[1]S&S'!$B:$F,5,0),) -> 1748 | K19: =IFERROR(VLOOKUP(A:A,[1]APO!$A:$F,6,0),) -> 0 | L19: =IFERROR(VLOOKUP(C:C,'[1]TOTAL APO'!$A:$B,2,0),) -> 0 | M19: =IFERROR(VLOOKUP(A:A,[1]Short!$A:$Q,17,0),) -> 0 | N19: =IFERROR(VLOOKUP(C:C,[1]GIT!$B:$D,3,0),) -> 291 | O19: =IFERROR(VLOOKUP(A:A,[2]Sheet1!$A:$B,2,0),) -> 0 | P19: =IFERROR(VLOOKUP(A:A,[2]Sheet1!$A:$B,2,0),) -> 0 | Q19: =+E19-P19 -> 750
A20: =F20&C20 -> C10240043571 | B20: =IF(J20>=SUMIFS(E:E,C:C,C20),"Good to go","Short in Qty") -> Good to go | C20: 40043571 | D20: *PA SC CLASSIC 84G M75 P48 | E20: 75 | F20: C102 | G20: Done | H20: Abhisekh M | I20: 30/12:02 | J20: =IFERROR(VLOOKUP(C:C,'[1]S&S'!$B:$F,5,0),) -> 1748 | K20: =IFERROR(VLOOKUP(A:A,[1]APO!$A:$F,6,0),) -> 0 | L20: =IFERROR(VLOOKUP(C:C,'[1]TOTAL APO'!$A:$B,2,0),) -> 0 | M20: =IFERROR(VLOOKUP(A:A,[1]Short!$A:$Q,17,0),) -> 0 | N20: =IFERROR(VLOOKUP(C:C,[1]GIT!$B:$D,3,0),) -> 291 | O20: =IFERROR(VLOOKUP(A:A,[2]Sheet1!$A:$B,2,0),) -> 75 | P20: =IFERROR(VLOOKUP(A:A,[2]Sheet1!$A:$B,2,0),) -> 75 | Q20: =+E20-P20 -> 0
A21: =F21&C21 -> KT0240043584 | B21: =IF(J21>=SUMIFS(E:E,C:C,C21),"Good to go","Short in Qty") -> Good to go | C21: 40043584 | D21: *PA SC GOOD MORNING 84G M75 P48 | E21: 700 | F21: KT02 | H21: Ajay Kitting | I21: 29/18:56 | J21: =IFERROR(VLOOKUP(C:C,'[1]S&S'!$B:$F,5,0),) -> 1145 | K21: =IFERROR(VLOOKUP(A:A,[1]APO!$A:$F,6,0),) -> 0 | L21: =IFERROR(VLOOKUP(C:C,'[1]TOTAL APO'!$A:$B,2,0),) -> 0 | M21: =IFERROR(VLOOKUP(A:A,[1]Short!$A:$Q,17,0),) -> 0 | N21: =IFERROR(VLOOKUP(C:C,[1]GIT!$B:$D,3,0),) -> 228 | O21: =IFERROR(VLOOKUP(A:A,[2]Sheet1!$A:$B,2,0),) -> 0 | P21: =IFERROR(VLOOKUP(A:A,[2]Sheet1!$A:$B,2,0),) -> 0 | Q21: =+E21-P21 -> 700
A22: =F22&C22 -> C12140043679 | B22: =IF(J22>=SUMIFS(E:E,C:C,C22),"Good to go","Short in Qty") -> Good to go | C22: 40043679 | D22: GP Color Play Shade 6 M370 70g P24 | E22: 2 | F22: C121 | G22: No Stock | H22: ADD plan | I22: 22/ | J22: =IFERROR(VLOOKUP(C:C,'[1]S&S'!$B:$F,5,0),) -> 19 | K22: =IFERROR(VLOOKUP(A:A,[1]APO!$A:$F,6,0),) -> 0 | L22: =IFERROR(VLOOKUP(C:C,'[1]TOTAL APO'!$A:$B,2,0),) -> 0 | M22: =IFERROR(VLOOKUP(A:A,[1]Short!$A:$Q,17,0),) -> 0 | N22: =IFERROR(VLOOKUP(C:C,[1]GIT!$B:$D,3,0),) -> 0 | O22: =IFERROR(VLOOKUP(A:A,[2]Sheet1!$A:$B,2,0),) -> 0 | P22: =IFERROR(VLOOKUP(A:A,[2]Sheet1!$A:$B,2,0),) -> 0 | Q22: =+E22-P22 -> 2
A23: =F23&C23 -> C12140050082 | B23: =IF(J23>=SUMIFS(E:E,C:C,C23),"Good to go","Short in Qty") -> Good to go | C23: 40050082 | D23: *GPSmoothRenewShampoo1000mlMRP2100PS9 | E23: 4 | F23: C121 | G23: No Stock | H23: ADD plan | I23: 22/ | J23: =IFERROR(VLOOKUP(C:C,'[1]S&S'!$B:$F,5,0),) -> 4 | K23: =IFERROR(VLOOKUP(A:A,[1]APO!$A:$F,6,0),) -> 0 | L23: =IFERROR(VLOOKUP(C:C,'[1]TOTAL APO'!$A:$B,2,0),) -> 0 | M23: =IFERROR(VLOOKUP(A:A,[1]Short!$A:$Q,17,0),) -> 0 | N23: =IFERROR(VLOOKUP(C:C,[1]GIT!$B:$D,3,0),) -> 0 | O23: =IFERROR(VLOOKUP(A:A,[2]Sheet1!$A:$B,2,0),) -> 0 | P23: =IFERROR(VLOOKUP(A:A,[2]Sheet1!$A:$B,2,0),) -> 0 | Q23: =+E23-P23 -> 4
A24: =F24&C24 -> C04640050209 | B24: =IF(J24>=SUMIFS(E:E,C:C,C24),"Good to go","Short in Qty") -> Good to go | C24: 40050209 | D24: GPDrkBlnd wth Brwn Reflc 6.870G M370 P24 | E24: 2 | F24: C046 | G24: Done | H24: Anurag | I24: 26/08:12 | J24: =IFERROR(VLOOKUP(C:C,'[1]S&S'!$B:$F,5,0),) -> 2 | K24: =IFERROR(VLOOKUP(A:A,[1]APO!$A:$F,6,0),) -> 0 | L24: =IFERROR(VLOOKUP(C:C,'[1]TOTAL APO'!$A:$B,2,0),) -> 0 | M24: =IFERROR(VLOOKUP(A:A,[1]Short!$A:$Q,17,0),) -> 0 | N24: =IFERROR(VLOOKUP(C:C,[1]GIT!$B:$D,3,0),) -> 0 | O24: =IFERROR(VLOOKUP(A:A,[2]Sheet1!$A:$B,2,0),) -> 2 | P24: =IFERROR(VLOOKUP(A:A,[2]Sheet1!$A:$B,2,0),) -> 2 | Q24: =+E24-P24 -> 0
A25: =F25&C25 -> C04340037927 | B25: =IF(J25>=SUMIFS(E:E,C:C,C25),"Good to go","Short in Qty") -> Good to go | C25: 40037927 | D25: GK SHAKTI MAC + 10 MAT M60 P72 | E25: 2 | F25: C043 | G25: Done | H25: APO | I25: 30/13:21 | J25: =IFERROR(VLOOKUP(C:C,'[1]S&S'!$B:$F,5,0),) -> 7.9166667 | K25: =IFERROR(VLOOKUP(A:A,[1]APO!$A:$F,6,0),) -> 0 | L25: =IFERROR(VLOOKUP(C:C,'[1]TOTAL APO'!$A:$B,2,0),) -> 0 | M25: =IFERROR(VLOOKUP(A:A,[1]Short!$A:$Q,17,0),) -> 0 | N25: =IFERROR(VLOOKUP(C:C,[1]GIT!$B:$D,3,0),) -> 0 | O25: =IFERROR(VLOOKUP(A:A,[2]Sheet1!$A:$B,2,0),) -> 2 | P25: =IFERROR(VLOOKUP(A:A,[2]Sheet1!$A:$B,2,0),) -> 2 | Q25: =+E25-P25 -> 0
A26: =F26&C26 -> C04840043584 | B26: =IF(J26>=SUMIFS(E:E,C:C,C26),"Good to go","Short in Qty") -> Good to go | C26: 40043584 | D26: *PA SC GOOD MORNING 84G M75 P48 | E26: 10 | F26: C048 | G26: Done | H26: Action | I26: 30/12:47 | J26: =IFERROR(VLOOKUP(C:C,'[1]S&S'!$B:$F,5,0),) -> 1145 | K26: =IFERROR(VLOOKUP(A:A,[1]APO!$A:$F,6,0),) -> 0 | L26: =IFERROR(VLOOKUP(C:C,'[1]TOTAL APO'!$A:$B,2,0),) -> 0 | M26: =IFERROR(VLOOKUP(A:A,[1]Short!$A:$Q,17,0),) -> 0 | N26: =IFERROR(VLOOKUP(C:C,[1]GIT!$B:$D,3,0),) -> 228 | O26: =IFERROR(VLOOKUP(A:A,[2]Sheet1!$A:$B,2,0),) -> 10 | P26: =IFERROR(VLOOKUP(A:A,[2]Sheet1!$A:$B,2,0),) -> 10 | Q26: =+E26-P26 -> 0
A27: =F27&C27 -> KT0240050629 | B27: =IF(J27>=SUMIFS(E:E,C:C,C27),"Good to go","Short in Qty") -> Good to go | C27: 40050629 | D27: *PASOAPGOODMORNING125GM80.00P108GCPL | E27: 128 | F27: KT02 | H27: Ajay Kitting | I27: 29/18:56 | J27: =IFERROR(VLOOKUP(C:C,'[1]S&S'!$B:$F,5,0),) -> 128.60185 | K27: =IFERROR(VLOOKUP(A:A,[1]APO!$A:$F,6,0),) -> 0 | L27: =IFERROR(VLOOKUP(C:C,'[1]TOTAL APO'!$A:$B,2,0),) -> 0 | M27: =IFERROR(VLOOKUP(A:A,[1]Short!$A:$Q,17,0),) -> 0 | N27: =IFERROR(VLOOKUP(C:C,[1]GIT!$B:$D,3,0),) -> 0 | O27: =IFERROR(VLOOKUP(A:A,[2]Sheet1!$A:$B,2,0),) -> 0 | P27: =IFERROR(VLOOKUP(A:A,[2]Sheet1!$A:$B,2,0),) -> 0 | Q27: =+E27-P27 -> 128
A28: =F28&C28 -> C04840042204 | B28: =IF(J28>=SUMIFS(E:E,C:C,C28),"Good to go","Short in Qty") -> Short in Qty | C28: 40042204 | D28: KS12'S RIBBED MRP 120P480 | E28: 10 | F28: C048 | G28: GIT Not Connected | H28: Action | I28: 30/12:47 | J28: =IFERROR(VLOOKUP(C:C,'[1]S&S'!$B:$F,5,0),) -> 0.0020833333 | K28: =IFERROR(VLOOKUP(A:A,[1]APO!$A:$F,6,0),) -> 0 | L28: =IFERROR(VLOOKUP(C:C,'[1]TOTAL APO'!$A:$B,2,0),) -> 0 | M28: =IFERROR(VLOOKUP(A:A,[1]Short!$A:$Q,17,0),) -> 0 | N28: =IFERROR(VLOOKUP(C:C,[1]GIT!$B:$D,3,0),) -> 0 | O28: =IFERROR(VLOOKUP(A:A,[2]Sheet1!$A:$B,2,0),) -> 0 | P28: =IFERROR(VLOOKUP(A:A,[2]Sheet1!$A:$B,2,0),) -> 0 | Q28: =+E28-P28 -> 10
A29: =F29&C29 -> C04240060029 | B29: =IF(J29>=SUMIFS(E:E,C:C,C29),"Good to go","Short in Qty") -> Good to go | C29: 40060029 | D29: AER MATIC SPRAY REFILL FLG 210ML M249P18 | E29: 15 | F29: C042 | G29: Done | H29: Yogesh Sir | I29: 30/12:50 | J29: =IFERROR(VLOOKUP(C:C,'[1]S&S'!$B:$F,5,0),) -> 1528 | K29: =IFERROR(VLOOKUP(A:A,[1]APO!$A:$F,6,0),) -> 0 | L29: =IFERROR(VLOOKUP(C:C,'[1]TOTAL APO'!$A:$B,2,0),) -> 0 | M29: =IFERROR(VLOOKUP(A:A,[1]Short!$A:$Q,17,0),) -> 0 | N29: =IFERROR(VLOOKUP(C:C,[1]GIT!$B:$D,3,0),) -> 0 | O29: =IFERROR(VLOOKUP(A:A,[2]Sheet1!$A:$B,2,0),) -> 15 | P29: =IFERROR(VLOOKUP(A:A,[2]Sheet1!$A:$B,2,0),) -> 15 | Q29: =+E29-P29 -> 0
A30: =F30&C30 -> C04640057084 | B30: =IF(J30>=SUMIFS(E:E,C:C,C30),"Good to go","Short in Qty") -> Good to go | C30: 40057084 | D30: GPCP9.26VRYLGHTBLNRDIRD M370 70G P24 | E30: 4 | F30: C046 | G30: Done | H30: Anurag | I30: 26/08:12 | J30: =IFERROR(VLOOKUP(C:C,'[1]S&S'!$B:$F,5,0),) -> 24 | K30: =IFERROR(VLOOKUP(A:A,[1]APO!$A:$F,6,0),) -> 0 | L30: =IFERROR(VLOOKUP(C:C,'[1]TOTAL APO'!$A:$B,2,0),) -> 0 | M30: =IFERROR(VLOOKUP(A:A,[1]Short!$A:$Q,17,0),) -> 0 | N30: =IFERROR(VLOOKUP(C:C,[1]GIT!$B:$D,3,0),) -> 0 | O30: =IFERROR(VLOOKUP(A:A,[2]Sheet1!$A:$B,2,0),) -> 4 | P30: =IFERROR(VLOOKUP(A:A,[2]Sheet1!$A:$B,2,0),) -> 4 | Q30: =+E30-P30 -> 0
A31: =F31&C31 -> C04640057095 | B31: =IF(J31>=SUMIFS(E:E,C:C,C31),"Good to go","Short in Qty") -> Good to go | C31: 40057095 | D31: GPCP4.26BRWNIRDSCNT RED M370 70G P24 | E31: 2 | F31: C046 | G31: Done | H31: Anurag | I31: 26/08:12 | J31: =IFERROR(VLOOKUP(C:C,'[1]S&S'!$B:$F,5,0),) -> 16 | K31: =IFERROR(VLOOKUP(A:A,[1]APO!$A:$F,6,0),) -> 0 | L31: =IFERROR(VLOOKUP(C:C,'[1]TOTAL APO'!$A:$B,2,0),) -> 0 | M31: =IFERROR(VLOOKUP(A:A,[1]Short!$A:$Q,17,0),) -> 0 | N31: =IFERROR(VLOOKUP(C:C,[1]GIT!$B:$D,3,0),) -> 0 | O31: =IFERROR(VLOOKUP(A:A,[2]Sheet1!$A:$B,2,0),) -> 2 | P31: =IFERROR(VLOOKUP(A:A,[2]Sheet1!$A:$B,2,0),) -> 2 | Q31: =+E31-P31 -> 0
A32: =F32&C32 -> C04640057096 | B32: =IF(J32>=SUMIFS(E:E,C:C,C32),"Good to go","Short in Qty") -> Good to go | C32: 40057096 | D32: GPCP12.13VRYLGTBLNDBEIG M370 70G P24 | E32: 2 | F32: C046 | G32: Done | H32: Anurag | I32: 26/08:12 | J32: =IFERROR(VLOOKUP(C:C,'[1]S&S'!$B:$F,5,0),) -> 14 | K32: =IFERROR(VLOOKUP(A:A,[1]APO!$A:$F,6,0),) -> 0 | L32: =IFERROR(VLOOKUP(C:C,'[1]TOTAL APO'!$A:$B,2,0),) -> 0 | M32: =IFERROR(VLOOKUP(A:A,[1]Short!$A:$Q,17,0),) -> 0 | N32: =IFERROR(VLOOKUP(C:C,[1]GIT!$B:$D,3,0),) -> 0 | O32: =IFERROR(VLOOKUP(A:A,[2]Sheet1!$A:$B,2,0),) -> 2 | P32: =IFERROR(VLOOKUP(A:A,[2]Sheet1!$A:$B,2,0),) -> 2 | Q32: =+E32-P32 -> 0
A33: =F33&C33 -> C04640057097 | B33: =IF(J33>=SUMIFS(E:E,C:C,C33),"Good to go","Short in Qty") -> Good to go | C33: 40057097 | D33: GPCP12.7VRYLGHTBLDE MAT M370 70G P24 | E33: 3 | F33: C046 | G33: Done | H33: Anurag | I33: 26/08:12 | J33: =IFERROR(VLOOKUP(C:C,'[1]S&S'!$B:$F,5,0),) -> 15 | K33: =IFERROR(VLOOKUP(A:A,[1]APO!$A:$F,6,0),) -> 0 | L33: =IFERROR(VLOOKUP(C:C,'[1]TOTAL APO'!$A:$B,2,0),) -> 0 | M33: =IFERROR(VLOOKUP(A:A,[1]Short!$A:$Q,17,0),) -> 0 | N33: =IFERROR(VLOOKUP(C:C,[1]GIT!$B:$D,3,0),) -> 0 | O33: =IFERROR(VLOOKUP(A:A,[2]Sheet1!$A:$B,2,0),) -> 3 | P33: =IFERROR(VLOOKUP(A:A,[2]Sheet1!$A:$B,2,0),) -> 3 | Q33: =+E33-P33 -> 0
A34: =F34&C34 -> C04240043461 | B34: =IF(J34>=SUMIFS(E:E,C:C,C34),"Good to go","Short in Qty") -> Short in Qty | C34: 40043461 | D34: PA REGAL 4X 130 ML M299 P18 GCPL | E34: 20 | F34: C042 | G34: GIT Not Connected | H34: Action | I34: 30/12:47 | J34: =IFERROR(VLOOKUP(C:C,'[1]S&S'!$B:$F,5,0),) -> 1 | K34: =IFERROR(VLOOKUP(A:A,[1]APO!$A:$F,6,0),) -> 0 | L34: =IFERROR(VLOOKUP(C:C,'[1]TOTAL APO'!$A:$B,2,0),) -> 0 | M34: =IFERROR(VLOOKUP(A:A,[1]Short!$A:$Q,17,0),) -> 0 | N34: =IFERROR(VLOOKUP(C:C,[1]GIT!$B:$D,3,0),) -> 0 | O34: =IFERROR(VLOOKUP(A:A,[2]Sheet1!$A:$B,2,0),) -> 0 | P34: =IFERROR(VLOOKUP(A:A,[2]Sheet1!$A:$B,2,0),) -> 0 | Q34: =+E34-P34 -> 20
A35: =F35&C35 -> C13140057406 | B35: =IF(J35>=SUMIFS(E:E,C:C,C35),"Good to go","Short in Qty") -> Good to go | C35: 40057406 | D35: PA GM AER 150ML M225 P24 TT | E35: 7 | F35: C131 | G35: No Stock | H35: Abhisekh M | I35: 15/12:42 | J35: =IFERROR(VLOOKUP(C:C,'[1]S&S'!$B:$F,5,0),) -> 7 | K35: =IFERROR(VLOOKUP(A:A,[1]APO!$A:$F,6,0),) -> 0 | L35: =IFERROR(VLOOKUP(C:C,'[1]TOTAL APO'!$A:$B,2,0),) -> 0 | M35: =IFERROR(VLOOKUP(A:A,[1]Short!$A:$Q,17,0),) -> 0 | N35: =IFERROR(VLOOKUP(C:C,[1]GIT!$B:$D,3,0),) -> 0 | O35: =IFERROR(VLOOKUP(A:A,[2]Sheet1!$A:$B,2,0),) -> 0 | P35: =IFERROR(VLOOKUP(A:A,[2]Sheet1!$A:$B,2,0),) -> 0 | Q35: =+E35-P35 -> 7
A36: =F36&C36 -> C13140057975 | B36: =IF(J36>=SUMIFS(E:E,C:C,C36),"Good to go","Short in Qty") -> Good to go | C36: 40057975 | D36: KS RUSH 120ML M99.00 P48 GCPL | E36: 150 | F36: C131 | G36: Done | H36: Abhisekh M | I36: 30/12:02 | J36: =IFERROR(VLOOKUP(C:C,'[1]S&S'!$B:$F,5,0),) -> 295 | K36: =IFERROR(VLOOKUP(A:A,[1]APO!$A:$F,6,0),) -> 0 | L36: =IFERROR(VLOOKUP(C:C,'[1]TOTAL APO'!$A:$B,2,0),) -> 0 | M36: =IFERROR(VLOOKUP(A:A,[1]Short!$A:$Q,17,0),) -> 0 | N36: =IFERROR(VLOOKUP(C:C,[1]GIT!$B:$D,3,0),) -> 0 | O36: =IFERROR(VLOOKUP(A:A,[2]Sheet1!$A:$B,2,0),) -> 150 | P36: =IFERROR(VLOOKUP(A:A,[2]Sheet1!$A:$B,2,0),) -> 150 | Q36: =+E36-P36 -> 0
A37: =F37&C37 -> C04340043461 | B37: =IF(J37>=SUMIFS(E:E,C:C,C37),"Good to go","Short in Qty") -> Short in Qty | C37: 40043461 | D37: PA REGAL 4X 130 ML M299 P18 GCPL | E37: 5 | F37: C043 | G37: No Stock | H37: Action | I37: 30/12:47 | J37: =IFERROR(VLOOKUP(C:C,'[1]S&S'!$B:$F,5,0),) -> 1 | K37: =IFERROR(VLOOKUP(A:A,[1]APO!$A:$F,6,0),) -> 0 | L37: =IFERROR(VLOOKUP(C:C,'[1]TOTAL APO'!$A:$B,2,0),) -> 0 | M37: =IFERROR(VLOOKUP(A:A,[1]Short!$A:$Q,17,0),) -> 0 | N37: =IFERROR(VLOOKUP(C:C,[1]GIT!$B:$D,3,0),) -> 0 | O37: =IFERROR(VLOOKUP(A:A,[2]Sheet1!$A:$B,2,0),) -> 0 | P37: =IFERROR(VLOOKUP(A:A,[2]Sheet1!$A:$B,2,0),) -> 0 | Q37: =+E37-P37 -> 5
A38: =F38&C38 -> C04840062265 | B38: =IF(J38>=SUMIFS(E:E,C:C,C38),"Good to go","Short in Qty") -> Good to go | C38: 40062265 | D38: AER MATIC SPRAY REF CSB 210ML M249P18 NP | E38: 50 | F38: C048 | G38: Done | H38: Action | I38: 30/12:47 | J38: =IFERROR(VLOOKUP(C:C,'[1]S&S'!$B:$F,5,0),) -> 352.99944 | K38: =IFERROR(VLOOKUP(A:A,[1]APO!$A:$F,6,0),) -> 0 | L38: =IFERROR(VLOOKUP(C:C,'[1]TOTAL APO'!$A:$B,2,0),) -> 0 | M38: =IFERROR(VLOOKUP(A:A,[1]Short!$A:$Q,17,0),) -> 0 | N38: =IFERROR(VLOOKUP(C:C,[1]GIT!$B:$D,3,0),) -> 0 | O38: =IFERROR(VLOOKUP(A:A,[2]Sheet1!$A:$B,2,0),) -> 50 | P38: =IFERROR(VLOOKUP(A:A,[2]Sheet1!$A:$B,2,0),) -> 50 | Q38: =+E38-P38 -> 0 | R38: 1
A39: =F39&C39 -> C04640058547 | B39: =IF(J39>=SUMIFS(E:E,C:C,C39),"Good to go","Short in Qty") -> Good to go | C39: 40058547 | D39: KS3'S LONGLAST SYNC M60 P480 | E39: 1 | F39: C046 | G39: Done | H39: Narendra | I39: 29/12:40 | J39: =IFERROR(VLOOKUP(C:C,'[1]S&S'!$B:$F,5,0),) -> 2 | K39: =IFERROR(VLOOKUP(A:A,[1]APO!$A:$F,6,0),) -> 0 | L39: =IFERROR(VLOOKUP(C:C,'[1]TOTAL APO'!$A:$B,2,0),) -> 0 | M39: =IFERROR(VLOOKUP(A:A,[1]Short!$A:$Q,17,0),) -> 0 | N39: =IFERROR(VLOOKUP(C:C,[1]GIT!$B:$D,3,0),) -> 0 | O39: =IFERROR(VLOOKUP(A:A,[2]Sheet1!$A:$B,2,0),) -> 0 | P39: =IFERROR(VLOOKUP(A:A,[2]Sheet1!$A:$B,2,0),) -> 0 | Q39: =+E39-P39 -> 1
A40: =F40&C40 -> C04340058547 | B40: =IF(J40>=SUMIFS(E:E,C:C,C40),"Good to go","Short in Qty") -> Good to go | C40: 40058547 | D40: KS3'S LONGLAST SYNC M60 P480 | E40: 1 | F40: C043 | G40: Done | H40: Narendra | I40: 29/12:40 | J40: =IFERROR(VLOOKUP(C:C,'[1]S&S'!$B:$F,5,0),) -> 2 | K40: =IFERROR(VLOOKUP(A:A,[1]APO!$A:$F,6,0),) -> 0 | L40: =IFERROR(VLOOKUP(C:C,'[1]TOTAL APO'!$A:$B,2,0),) -> 0 | M40: =IFERROR(VLOOKUP(A:A,[1]Short!$A:$Q,17,0),) -> 0 | N40: =IFERROR(VLOOKUP(C:C,[1]GIT!$B:$D,3,0),) -> 0 | O40: =IFERROR(VLOOKUP(A:A,[2]Sheet1!$A:$B,2,0),) -> 0 | P40: =IFERROR(VLOOKUP(A:A,[2]Sheet1!$A:$B,2,0),) -> 0 | Q40: =+E40-P40 -> 1
...

Sheet Indent
F1: SL No | G1: Date | H1: From | I1: To | J1: Truck Type | K1: Reported Truck Type | L1: Transporter | M1: Indent Date | N1: Indent Time | O1: Placed | P1: Reported date | Q1: Reported time | R1: Indent No | S1: Vehicle no | T1: Remarks | U1: Plan time | V1: Dock Number | W1: S. time | X1: E . Time | Y1: Sup Name | Z1: Plan Qty | AA1: Load Qty | AB1: Ship No | AC1: Gr.Wt | AD1: EQW
F2: 1 | G2: 46325 | H2: BHIWANDI | I2: INDORE | J2: 18MT | K2: 18MT | L2: ADVAY ( COLD STAR ) | M2: 46321 | N2: 0.49583333 | O2: Y | P2: 46325 | Q2: 0.43402778 | R2: GCPL-C121-O-12948 | S2: RJ32GE1521 | T2: Loading Done | U2: 0.53333333 | V2: 12 | W2: 0.58263889 | X2: 0.69513889 | Y2: Sanjay | Z2: =180+37+1236 -> 1453 | AA2: 1453 | AB2: 1001154222 | AC2: =1243+170.7+14534.361 -> 15948.061 | AD2: =1616.289+17389.474 -> 19005.763
F3: 2 | G3: 46325 | H3: BHIWANDI | I3: AHMD | J3: 18MT | K3: 37MT | L3: KAPOOR | M3: 46324 | N3: 0.48055556 | O3: Y | P3: 46325 | Q3: 0.45138889 | R3: GCPL-C121-O-12947 | S3: RJ09GE6858 | T3: Loading Done | U3: 0.625 | V3: 17 | W3: 0.66666667 | X3: 0.88611111 | Y3: Siddesh | Z3: 3050 | AA3: 3050 | AB3: 1001154452 | AC3: 27515.967 | AD3: 40473.011
F4: 3 | G4: 46325 | H4: BHIWANDI | I4: PONDY | J4: 18MT | K4: 15MT | L4: KAPOOR | M4: 46324 | N4: 0.57569444 | O4: Y | P4: 46325 | Q4: 0.4375 | R4: GCPL-C121-O-12949 | S4: NL01AG6386
F5: 4 | G5: 46325 | H5: BHIWANDI | I5: PONDY | J5: 18MT | K5: 18MT | L5: KAPOOR | M5: 46324 | N5: 0.57569444 | O5: y | P5: 46325 | Q5: 0.44097222 | R5: GCPL-C121-O-12950 | S5: NL01AG5387 | T5: Loading Done | U5: 0.50694444 | V5: 11 | W5: 0.58333333 | X5: 0.71875 | Y5: Aman | Z5: 1997 | AA5: 1997 | AB5: 1001154404 | AC5: 16967.6 | AD5: 20896.063
F6: 5 | G6: 46325 | H6: BHIWANDI | I6: INDORE | J6: 18MT | L6: ADVAY | M6: 46324 | N6: 0.57569444 | R6: GCPL-C121-O-12951
F7: 6 | G7: 46325 | H7: BHIWANDI | I7: PUNE | J7: 18MT | K7: 10MT | L7: COLDSTAR ( SUBHAM ) | M7: 46324 | N7: 0.57569444 | O7: Y | P7: 46325 | Q7: 0.43055556 | R7: GCPL-C121-O-12952 | S7: MH14KA5365 | T7: Loading Done | U7: 0.66875 | V7: 14 | W7: 0.73611111 | X7: 0.80208333 | Y7: Manmohan Yadav | Z7: 830 | AA7: 830 | AB7: 1001154408 | AC7: 7949.36 | AD7: 8720.856
F8: 7 | G8: 46325 | H8: BHIWANDI | I8: PUNE | J8: 18MT | K8: 18MT | L8: COLDSTAR ( ANAND ) | M8: 46324 | N8: 0.57569444 | O8: Y | P8: 46325 | Q8: 0.5625 | R8: GCPL-C121-O-12953 | S8: MH12UM3900 | T8: Loading Done | U8: 0.66111111 | V8: 15 | W8: 0.71875 | X8: 0.88402778 | Y8: Rakesh | Z8: 1764 | AA8: 1764 | AB8: 1001154453 | AC8: 14978.778 | AD8: 21423.254
F9: 8 | G9: 46325 | H9: BHIWANDI | I9: PUNE | J9: 18MT | K9: 15MT | L9: COLDSTAR | M9: 46324 | N9: 0.57569444 | O9: Y | P9: 46325 | Q9: 0.61805556 | R9: GCPL-C121-O-12954 | S9: RJ11GC5155 | T9: Loading Done | U9: 0.68263889 | V9: 16 | W9: 0.71597222 | X9: 0.84027778 | Y9: Jeet | Z9: 1220 | AA9: 1220 | AB9: 1001154437 | AC9: 14293.705 | AD9: 15983.543
F10: 9 | G10: 46325 | H10: BHIWANDI | I10: TEPLA | J10: 18MT | K10: 18MT | L10: ONE Point | M10: 46324 | N10: 0.57569444 | O10: Y | P10: 46324 | Q10: 0.55277778 | R10: GCPL-C121-M-12966 | S10: HR68C2473 | T10: Loading Done | U10: 0.64444444 | V10: 12 | W10: 0.71875 | X10: 0.85069444 | Y10: Sanjay | Z10: 2663 | AA10: 2663 | AB10: 1001154450 | AC10: 17934.84 | AD10: 25103.073
F11: 10 | G11: 46325 | H11: BHIWANDI | I11: KOLKATA | J11: 18MT | K11: 18MT | L11: GATIVIDHI | M11: 46324 | N11: 0.57569444 | O11: Y | P11: 46325 | Q11: 0.44444444 | R11: GCPL-C121-O-12968 | S11: NL01AB9631 | T11: Loading Done | U11: 0.7125 | V11: 11 | W11: 0.8125 | X11: 0.96875 | Y11: Aman | Z11: 2145 | AA11: 2145 | AB11: 1001154455 | AC11: 16763.352 | AD11: 24139.025
F12: 11 | G12: 46325 | H12: BHIWANDI | I12: RAIPUR | J12: 18MT | K12: 18MT | L12: KAPOOR | M12: 46324 | N12: 0.99930556 | O12: Y | P12: 46325 | Q12: 0.5 | R12: GCPL-C121-O-12962 | S12: NL01AJ7158
F13: 12 | G13: 46325 | H13: BHIWANDI | I13: NAGPUR | J13: 18MT | K13: 15MT | L13: ADVAY | M13: 46324 | N13: 0.99930556 | O13: Y | P13: 46325 | Q13: 0.4375 | R13: GCPL-C121-O-12963 | S13: MH04JU1277 | T13: Loading Done | U13: 0.72916667 | V13: 16 | W13: 0.8625 | X13: 0.97430556 | Y13: Jeet | Z13: 1780 | AA13: 1780 | AB13: 1001154456 | AC13: 14012.53 | AD13: 21746.141
F14: 13 | G14: 46325 | H14: BHIWANDI | I14: AHMD | J14: 18MT | K14: 18MT | L14: KAPOOR | M14: 46324 | N14: 0.99930556 | O14: Y | P14: 46325 | Q14: 0.46527778 | R14: GCPL-C121-O-12964 | S14: NL01AE2938 | T14: Loading Done | U14: 0.63819444 | V14: 18 | W14: 0.70138889 | X14: 0.84722222 | Y14: Bahadur | Z14: 2137 | AA14: 2137 | AB14: 1001154451 | AC14: 17296.923 | AD14: 23967.032
F15: 14 | G15: 46325 | H15: BHIWANDI | I15: PUNE | J15: 10MT | K15: 10MT | L15: SUBHAM | M15: 46324 | N15: 0.57569444 | O15: Y | P15: 46325 | Q15: 0.42361111 | R15: GCPL-C121-M-12965 | S15: MH14NP2249 | T15: Loading Done | U15: 0.68958333 | V15: 11 | W15: 0.73611111 | X15: 0.79166667 | Y15: Aman | Z15: 670 | AA15: 670 | AB15: 1001154406 | AC15: 8738.16 | AD15: 7947.428
F16: 15 | G16: 46325 | H16: BHIWANDI | I16: PONDY | J16: 25MT | K16: 25MT | L16: KAPOOR | M16: 46325 | N16: 0.54166667 | O16: Y | P16: 46325 | Q16: 0.625 | R16: GCPL-C121-M-12967 | S16: NL01AJ7792 | T16: Loading Done | U16: 0.70208333 | V16: 14 | W16: 0.82638889 | X16: 0.99305556 | Y16: Manmohan Yadav | Z16: 3252 | AA16: 3252 | AB16: 1001154457 | AC16: 24923.414 | AD16: 34477.009
T22: Plan Will Share in 30 Minutes
T23: Loading In Process
T24: Plan Done, Loading Start Shortly
T25: Loading Done
T26: Manual Indent, As Confirmed by Rohan Sir

Sheet C042-1
A5: GODREJ CONSUMER PRODUCTS LTD
A6: C/O RPM Logistics Pvt Ltd. Add- E - 2 Vadpa Village BHIWANDI-421302
A7: Loading Sheet | C7: GATE NO: | E7: Plan Time: 11:43
A8: Transport Name | B8: Transfer-1 | C8: 808950644 | E8: Date | F8: 30.10.2026 | G8: Weight
A9: Vehicle no | E9: Start Time | G9: Volum
A10: Destination | B10: C042-1 | E10: End Time | G10: Indent
A11: Driver No
A12: Code | B12: Description | C12: Del Qty | D12: Priority | E12: MRP | F12: PKD | G12: Load Qty | H12: Remarks
A13: 40060030 | B13: AER MATIC REFILL ALIVE 225ML M249P18 | C13: 20 | I13: 1001154266
A14: 40060034 | B14: AER MATIC SPRY RFILL VVB 210ML M249P18 | C14: 30 | I14: 7000640913
A15: 40062464 | B15: AER O ORANGE PUNCH 7.5G M99P60 | C15: 20 | I15: 4400600744
A16: 40063614 | B16: AER MATC CMBI RYL VANILLA 210ML P6 M599 | C16: 50
A17: 40063756 | B17: CIN LIME 38G SING M10 P216 RSTRD | C17: 50
A20: Driver Sign | C20: =SUM(C13:C19) -> 170 | D20: Loading Total
A21: Supervisor Sign | D21: Checked By
A23: Sr.No. | B23: Delivery No | C23: Del Qty | D23: Total Scan | E23: pending
A24: 1
A25: 2
A26: 3
B27: Total
B30: RJ32GE1521
B31: R R - 7742794054
B32: Indore-1 - GCPL-C121-M-12961
A33: 40061668 | B33: PA GM NEW AER 150ML M225 P48 | C33: 80 | I33: 1001154222 | J33: 1243.2
A34: 40065477 | B34: PA EDP HARMONY 100ML M599P10 GT(10+2) RE | C34: 50 | I34: 1006207664 | J34: 16359.278
A35: 40065478 | B35: PA EDP CONQ 100ML M599P10 GT(10+2) RE | C35: 50 | I35: 5128391
C37: =SUBTOTAL(9,C33:C36) -> 180

Sheet PONDY-1
I1: 16967.6 | J1: 52596511
A5: GODREJ CONSUMER PRODUCTS LTD
A6: C/O RPM Logistics Pvt Ltd. Add- E - 2 Vadpa Village BHIWANDI-421302
A7: Loading Sheet | C7: GATE NO: | E7: Plan Time: 12:10
A8: Transport Name | B8: KAPOOR | C8: 808950690 | E8: Date | F8: 30.10.2026 | G8: Weight | H8: 17MT
A9: Vehicle no | B9: NL01AG5387 | E9: Start Time | G9: Volum | H9: 55000
A10: Destination | B10: PONDY-1 | E10: End Time | G10: Indent
A11: Driver No | B11: RR. 7534849193 | G11: GCPL-C121-O-12950
A12: Code | B12: Description | C12: Del Qty | D12: Priority | E12: MRP | F12: PKD | G12: Load Qty | H12: Remarks | I12: 4400600750
A13: 40064876 | B13: GODREJ FAB 2KG P6 M309 FL | C13: 500
A14: 40064990 | B14: GODREJ HAIRLAB SS NATBLACK M229 P24ECOM | C14: 100 | J14: 1001154404
A15: 40064913 | B15: HIT RAT GLUE 25G M65 P100 BLUE ART | C15: 289 | J15: 1006209890
A16: 40064907 | B16: HIT RAT GLUE 50G M130 P50 BLUE ART | C16: 13 | J16: 5128507
A17: 40063540 | B17: PA DEO-SIGN VOYAGE 190ML M299 P72 | C17: 150
A18: 40057243 | B18: PA EDP OUD 100ML M599 P12 MT | C18: 800
A19: 40061668 | B19: PA GM NEW AER 150ML M225 P48 | C19: 5
A20: 40049949 | B20: PA SIGNATURE COLLECTION KIT M899P6 | C20: 140
A24: Driver Sign | C24: =SUM(C13:C23) -> 1997 | D24: Loading Total
A25: Supervisor Sign | D25: Checked By
A27: Sr.No. | B27: Delivery No | C27: Del Qty | D27: Total Scan | E27: pending
A28: 1
A29: 2
A30: 3
B31: Total

Sheet Indore-1
A5: GODREJ CONSUMER PRODUCTS LTD
A6: C/O RPM Logistics Pvt Ltd. Add- E - 2 Vadpa Village BHIWANDI-421302
A7: Loading Sheet | C7: GATE NO: | E7: Plan Time: 12:48
A8: Transport Name | B8: Coldstar | C8: 808950772 | E8: Date | F8: 30.10.2026 | G8: Weight | H8: 18MT
A9: Vehicle no | B9: RJ32GE1521 | C9: 808952393 | E9: Start Time | G9: Volum | H9: 53000
A10: Destination | B10: Indore-1 | E10: End Time | G10: Indent
A11: Driver No | B11: R R - 8000276529 | G11: GCPL-C121-O-12948
A12: Code | B12: Description | C12: Del Qty | D12: Priority | E12: MRP | F12: PKD | G12: Load Qty | H12: Remarks
A13: 40043571 | B13: *PA SC CLASSIC 84G M75 P48 | C13: 4 | J13: 1001154400
A14: 40063614 | B14: AER MATC CMBI RYL VANILLA 210ML P6 M599 | C14: 115
A15: 40063757 | B15: CIN HEALTH+ 38G NEW M10 P216 RSTRD | C15: 26 | D15: GIT
A16: 40065039 | B16: CIN ORG100G PO4 M175 P36 NEW MT | C16: 15 | D16: GIT | J16: 1006209846
A17: 40062023 | B17: EXPCRM 11G NBLK M15 P240 ND | C17: 142 | J17: 5128502
A18: 40064886 | B18: EZEE 500G M140 P24 50 % PCR | C18: 666
A19: 40065373 | B19: GODREJ FAB 800GM POUCH M99P14 | C19: 115 | J19: 1006209845
A20: 40041349 | B20: GP ColourPlay Shade 11.6 70g M370P24 | C20: 4 | J20: 5128501
A21: 40039418 | B21: GP Dimension Dev 10Vol 1000ml M800 P9 | C21: 5
A22: 40039359 | B22: GP Dimension Dev 20Vol 1000ml M800 P9 | C22: 10
A23: 40064248 | B23: GP DIMENSION SHADE 4G M440 70G P24 | C23: 10
A24: 40057096 | B24: GPCP12.13VRYLGTBLNDBEIG M370 70G P24 | C24: 2
A25: 40057097 | B25: GPCP12.7VRYLGHTBLDE MAT M370 70G P24 | C25: 3
A26: 40057095 | B26: GPCP4.26BRWNIRDSCNT RED M370 70G P24 | C26: 2
A27: 40057084 | B27: GPCP9.26VRYLGHTBLNRDIRD M370 70G P24 | C27: 4
A28: 40050209 | B28: GPDrkBlnd wth Brwn Reflc 6.870G M370 P24 | C28: 2
A29: 40062385 | B29: KS SPARK AER 120 ML M99 P48 NFR | C29: 3
A30: 40065157 | B30: KS SPARK MEGA 180ML M299 P72 NFR | C30: 40
A31: 40059656 | B31: KS SPARK POCKET 18ML M70 P160 GCPL | C31: 9
A32: 40059679 | B32: KS URGE POWSERIES 135ML M199 P24 GCPL | C32: 33
... A48: 40064088 | B48: PA NEO REFRESH 150ML B1G1 M250 P24 | C48: 14
A49: 40064428 | B49: PA SOAP PURE LXRY125GB3G1 M240 P27 N | C49: 1 | D49: GIT
A50: 40060646 | B50: PA STORM AER 150ML M225 P48 GCPL | C50: 1
A51: 40060423 | B51: PA TBLM (5+1) 40+8TSTR M225 P40 (8*6)INR | C51: 2
A52: 40059648 | B52: PA VOYAGE POCKET 18ML M70 P160 GCPL | C52: 2
A53: 40062347 | B53: SPIC TC 1L M189 P12 | C53: 100
A55: Driver Sign | C55: =SUM(C13:C54) -> 1391 | D55: Loading Total
A56: Supervisor Sign | D56: Checked By
A58: Sr.No. | B58: Delivery No | C58: Del Qty | D58: Total Scan | E58: pending
A59: 1
A60: 2
A61: 3
...

Sheet C042-2
A5: GODREJ CONSUMER PRODUCTS LTD
A6: C/O RPM Logistics Pvt Ltd. Add- E - 2 Vadpa Village BHIWANDI-421302
A7: Loading Sheet | C7: GATE NO: | E7: Plan Time: 14:46
A8: Transport Name | B8: Transfer - 2 | C8: 808952356 | E8: Date | F8: 30.10.2026 | G8: Weight
A9: Vehicle no | E9: Start Time | G9: Volum
A10: Destination | B10: C042-2 | E10: End Time | G10: Indent
A11: Driver No
A12: Code | B12: Description | C12: Del Qty | D12: Priority | E12: MRP | F12: PKD | G12: Load Qty | H12: Remarks
A13: 40050728 | B13: *CIN SHAVING CREAM 20GLIME FRESH M27P72 | C13: 3 | D13: APO
A14: 40060030 | B14: AER MATIC REFILL ALIVE 225ML M249P18 | C14: 115 | D14: APO
A15: 40060034 | B15: AER MATIC SPRY RFILL VVB 210ML M249P18NF | C15: 30 | D15: APO | I15: 1001154347
A16: 40063169 | B16: AER PO4 POCKET ASRTED 40G M260 P36MT NWA | C16: 7 | D16: APO | I16: 7000640945
A17: 40063022 | B17: AER PO5 PWRPCKT ASSORTED M350P24 ECOM NF | C17: 70 | D17: APO
A18: 40063753 | B18: AER SPRAY COOLAQUA 180ML M99P24 | C18: 121 | D18: APO
A19: 40063689 | B19: AER SPRAY MYSTIC MUSK 180ML M99P24 | C19: 14 | D19: APO
A20: 40049729 | B20: AER SPRAY VIOLET VALLEY 220ml M99P24 | C20: 106 | D20: APO
A21: 40063016 | B21: EXPCRM 20G+20ML+2ML DBRN PO10 P240 M40ND | C21: 13 | D21: APO
A22: 40063427 | B22: EXPERT CRÃˆME NAT BWN PO8 M40 P240-MT ND | C22: 4 | D22: APO
A23: 40063605 | B23: GENTEEL 2KG POUCH M360P6 FL MT PRF | C23: 3 | D23: APO
A24: 40063606 | B24: GENTEEL 4KG POUCH M660 P3 TL PRF | C24: 10 | D24: APO
A25: 40063604 | B25: GENTEEL TL 2KG POUCH M340 P6 NEWPRF | C25: 182 | D25: APO | F25: 181
A26: 40065335 | B26: GK ACTIV+PO2 REFILL M185P120 RNF PCR ROI | C26: 1 | D26: APO
A27: 40065291 | B27: GODREJ FAB 4 KG MT POUCH M525 P3 | C27: 715 | D27: APO
A28: 40064109 | B28: GODREJ XPRSS SHC NTBLCK18MLPO4P36M120 ND | C28: 10 | D28: APO
A29: 40050411 | B29: HIT ANTI ROACH M199.00 P30 | C29: 41 | D29: APO
A30: 40063489 | B30: HIT FIK 625ML M350P25 .18MM 28% MFT NEW | C30: 16 | D30: APO
C32: =SUM(C13:C31) -> 1461
A34: Code | B34: Description | C34: Del Qty | D34: Priority | E34: MRP | F34: PKD | G34: Load Qty | H34: Remarks
A35: 40065157 | B35: KS SPARK MEGA 180ML M299 P72 NFR | C35: 150
A36: 40062519 | B36: KS10'S RIBBED M100 P480 NEWAW | C36: 5 | I36: 808952334
A37: 40064503 | B37: NO1 LIME&ALO 100GP5 M125 P36 RSTRD NF2 | C37: 1 | I37: 808952335
A38: 40064375 | B38: PA ALTER EGO NEW AER 150ML M250 P48 | C38: 2
A39: 40050073 | B39: PA EDP GOOD MORNING 50ML G M399 P12 | C39: 7
A40: 40057243 | B40: PA EDP OUD 100ML M599 P12 MT | C40: 100
A41: 40061668 | B41: PA GM NEW AER 150ML M225 P48 | C41: 150
A42: 40061999 | B42: PA GM POCKET 18ML M70 P160 GCPL | C42: 44
A43: 40063539 | B43: PA NEO NEW AER 190ML M299 P72 | C43: 100
A44: 40049949 | B44: PA SIGNATURE COLLECTION KIT M899P6 | C44: 80
C46: =SUM(C35:C45) -> 639
A47: Driver Sign | D47: Loading Total
...

Sheet C042-3
A5: GODREJ CONSUMER PRODUCTS LTD
A6: C/O RPM Logistics Pvt Ltd. Add- E - 2 Vadpa Village BHIWANDI-421302
A7: Loading Sheet | C7: GATE NO: | E7: Plan Time: 14:49
A8: Transport Name | B8: C042-3 | E8: Date | F8: 30.10.2026 | G8: Weight
A9: Vehicle no | E9: Start Time | G9: Volum
A10: Destination | B10: Transfer-3 | E10: End Time | G10: Indent
A11: Driver No
A12: Code | B12: Description | C12: Del Qty | D12: Priority | E12: MRP | F12: PKD | G12: Load Qty | H12: Remarks
A13: 40050411 | B13: HIT ANTI ROACH M199.00 P30 | C13: 60 | E13: 60 | K13: =+C13-'C042-2'!C24 -> 50
A14: 40050728 | B14: *CIN SHAVING CREAM 20GLIME FRESH M27P72 | C14: 2 | E14: 2 | K14: =+C14-'C042-2'!C25 -> -180
A15: 40060034 | B15: AER MATIC SPRY RFILL VVB 210ML M249P18NF | C15: 19 | E15: 19 | K15: =+C15-'C042-2'!C26 -> 18
A16: 40063489 | B16: HIT FIK 625ML M350P25 .18MM 28% MFT NEW | C16: 12 | E16: 12 | I16: 7000640967 | K16: =+C16-'C042-2'!C27 -> -703
A17: 40063689 | B17: AER SPRAY MYSTIC MUSK 180ML M99P24 | C17: 22 | E17: 22 | K17: =+C17-'C042-2'!C28 -> 12
A18: 40063753 | B18: AER SPRAY COOLAQUA 180ML M99P24 | C18: 119 | E18: 119 | K18: =+C18-'C042-2'!C29 -> 78
A19: 40065335 | B19: GK ACTIV+PO2 REFILL M185P120 RNF PCR ROI | C19: 3 | E19: 3 | K19: =+C19-'C042-2'!C30 -> -13
A20: 40060033 | B20: AER MATIC REFILL PASSION 225ML M249P18 | C20: 141 | E20: 141
A21: 40060029 | B21: AER MATIC SPRAY REFILL FLG 210ML M249P18 | C21: 15 | E21: 15
A22: 40062345 | B22: AER O CARAMEL LATTE 7.5G M99P60 | C22: 10 | E22: 10
A23: 40063752 | B23: AER SPRAY CITRUS BLAST 180ML M99P24 | C23: 56 | E23: 0
A24: 40063700 | B24: AER SPRAY FOREST FRESH 180ML M99P24 | C24: 52 | E24: 52
A25: 40041526 | B25: AER SPRAY FRESHLUSHGREEN220ml M169P24new | C25: 30 | E25: 30
A26: 40063699 | B26: AER SPRAY JASMINEDELIGHT 180ML M99P24 | C26: 33 | E26: 33
A27: 40063688 | B27: AER SPRAY LAVENDERBLOOM 180ML M99P24 | C27: 106 | E27: 106
A28: 40063747 | B28: AER SPRAY ROSEBLOSSOM 180ML M99P24 | C28: 62 | E28: 62
A29: 40063794 | B29: AER SPRAY SANDAL BLISS 180ML M99P24 | C29: 4 | E29: 4
A30: 40049654 | B30: Cin Lime Bdywash Bottle 200ml M 120P30 | C30: 5 | E30: 5
A31: 40049658 | B31: Cin Org Bdywash Bottle 200ml M120 P30 | C31: 20 | E31: 20
... A51: 40064913 | B51: HIT RAT GLUE 25G M65 P100 BLUE ART | C51: 6 | E51: 6
A53: Driver Sign | C53: =SUM(C13:C51) -> 1491 | D53: Loading Total | E53: =SUM(E13:E52) -> 1435
A54: Supervisor Sign | D54: Checked By
A56: Sr.No. | B56: Delivery No | C56: Del Qty | D56: Total Scan | E56: pending
A57: 1
A58: 2
A59: 3
B60: Total

Sheet C042-4
A5: GODREJ CONSUMER PRODUCTS LTD
A6: C/O RPM Logistics Pvt Ltd. Add- E - 2 Vadpa Village BHIWANDI-421302
A7: Loading Sheet | C7: GATE NO: | E7: Plan Time: 14:50
A8: Transport Name | B8: C042-4 | E8: Date | F8: 30.10.2026 | G8: Weight
A9: Vehicle no | E9: Start Time | G9: Volum
A10: Destination | B10: Transfer-4 | E10: End Time | G10: Indent
A11: Driver No
A12: Code | B12: Description | C12: Del Qty | D12: Priority | E12: MRP | F12: PKD | G12: Load Qty | H12: Remarks
A13: 40063018 | B13: AERPOWERPOCKET BERRYRUSH 10G M70P120 NF | C13: 119 | E13: 119
A14: 40063025 | B14: AERPWRPCKT JASFLORDELI 10G M70P120 NF | C14: 200 | E14: 200
A15: 40063021 | B15: AERPWRPCKT LAV BLOOM 10G M70P120NP | C15: 14 | E15: 14
A16: 40063421 | B16: AERPWRPCKT LEMTANGYDEL 10G M70P120 | C16: 100 | E16: 100
A17: 40063020 | B17: AERPWRPCKT ROSEFRBLOSSM 10G M70P120NP NF | C17: 44 | E17: 44 | I17: 808952947
A18: 40064998 | B18: CIN COOL 100G SINGLES M45 P150 NEW RSTRD | C18: 6 | E18: 6
A19: 40063757 | B19: CIN HEALTH+ 38G NEW M10 P216 RSTRD | C19: 99 | E19: 99 | I19: 7000640969
A20: 40064999 | B20: CIN LIME 100G SINGLES M45 P150 NEW RSTRD | C20: 55 | E20: 0
A21: 40064157 | B21: CIN LIME 75G PO4M105 P50 RSTRD | C21: 174 | E21: 0
A22: 40060535 | B22: CIN SHAVING CREAM LIME FRESH 78G M80 P72 | C22: 2 | E22: 2
A23: 40060996 | B23: CIN SHAVING CREAM MENTHOL 78G M80P72 | C23: 34 | E23: 34
A24: 40061000 | B24: CINORIGINALTALC300G M190 P24 | C24: 5 | E24: 5
A25: 40063179 | B25: EXPCRM 20G+20G+2ML P010 NBLK P240 M40 ND | C25: 88 | E25: 88
A26: 40064886 | B26: EZEE 500G M140 P24 50 % PCR | C26: 177 | E26: 29
A27: 40065002 | B27: GODPROTEKTNEEM9GM110P40 (11+1) | C27: 1 | E27: 0
A28: 40062518 | B28: KS20'S RIBBED M200 P480 NEWAW | C28: 20 | E28: 20
A29: 40064855 | B29: NO1 COCONM 100G PO5 M115 P36 NDRSTRD NF2 | C29: 1 | E29: 0
A30: 40049906 | B30: PA AMAZONWOODS 120ML M349 P24 GCPL | C30: 147 | E30: 147
A31: 40064472 | B31: PA EDP TWINPCK EUPHO+ HARMONY M1599P10 | C31: 30 | E31: 30
... A35: 40064558 | B35: PA SOAPGOOD MRNG4X125GPO4M320 P27GCPL | C35: 40 | E35: 40
A37: Driver Sign | C37: =SUM(C13:C36) -> 1451 | D37: Loading Total | E37: =SUM(E13:E36) -> 1072
A38: Supervisor Sign | D38: Checked By
A40: Sr.No. | B40: Delivery No | C40: Del Qty | D40: Total Scan | E40: pending
A41: 1
A42: 2
A43: 3
B44: Total

Sheet AHMD-1
I1: 16930.32 | J1: 62793227
I2: 7671.96 | J2: 29545351
A5: GODREJ CONSUMER PRODUCTS LTD
A6: C/O RPM Logistics Pvt Ltd. Add- E - 2 Vadpa Village BHIWANDI-421302
A7: Loading Sheet | C7: GATE NO: | E7: Plan Time: 15:00
A8: Transport Name | B8: Kapoor | C8: 808951579 | E8: Date | F8: 30.10.2026 | G8: Weight | H8: 25MT
A9: Vehicle no | B9: RJ09GE6858 | C9: 808951584 | E9: Start Time | G9: Volum | H9: 10000
A10: Destination | B10: AHMD-1 | C10: 808952866 | E10: End Time | G10: Indent
A11: Driver No | B11: R R - 7974907236 | C11: 808951594 | G11: GCPL-C121-O-12947
A12: Code | B12: Description | C12: Del Qty | D12: Priority | E12: MRP | F12: PKD | G12: Load Qty | H12: Remarks
A13: 40060030 | B13: AER MATIC REFILL ALIVE 225ML M249P18 | C13: 100
A14: 40065278 | B14: AER PLUG VIOLET BLOOM 1M+2R M275P24 NC | C14: 150
A15: 40063747 | B15: AER SPRAY ROSEBLOSSOM 180ML M99P24 | C15: 105
A16: 40063018 | B16: AERPOWERPOCKET BERRYRUSH 10G M70P120 NF | C16: 100
A17: 40063025 | B17: AERPWRPCKT JASFLORDELI 10G M70P120 NF | C17: 150
A18: 40063021 | B18: AERPWRPCKT LAV BLOOM 10G M70P120NP | C18: 200 | I18: 1006210212
A19: 40063020 | B19: AERPWRPCKT ROSEFRBLOSSM 10G M70P120NP NF | C19: 100 | I19: 5128546
A20: 40064562 | B20: CIN LIME 150G PO5 M330 P12 NEW MT RSTRD | C20: 200
A21: 40062023 | B21: EXPCRM 11G NBLK M15 P240 ND | C21: 200
A22: 40063178 | B22: EXPCRM 20G+20ML+2ML BKBRN PO10P240M40ND | C22: 126
A23: 40063168 | B23: EXPCRM 20G+20ML+2ML P010 NTBRN P240M40ND | C23: 215
A24: 40065917 | B24: GK FLASH COMBI M120 P60 RNF PCB ROI | C24: 200
A25: 40065915 | B25: GK FLASH LAV COMBI M120 P60 RNF PCB | C25: 157
A26: 40065336 | B26: GK FLASHREFILL PO4 M365P60 EC RNF CAF RS | C26: 128
A27: 40060517 | B27: GODMAGCRTMHWNEEMREF9GP18 M10P360SRP20MT | C27: 100
A28: 40063483 | B28: HIT CIK 200ML M110 P60 0.18MM NEW L 33% | C28: 220
A29: 40060914 | B29: NO1 SAN TUR 150G PO4 M190P24MT ND RSTRD | C29: 300
C31: =SUM(C13:C30) -> 2751
B32: AHMD-1 - 808951594
A33: Code | B33: Description | C33: Del Qty | D33: Priority | E33: MRP | F33: PKD | G33: Load Qty | H33: Remarks
A34: 40049906 | B34: PA AMAZONWOODS 120ML M349 P24 GCPL | C34: 50
A35: 40060737 | B35: PA ASL GM 45ML TRAVEL PACK G M85P72 | C35: 5
A36: 40050073 | B36: PA EDP GOOD MORNING 50ML G M399 P12 | C36: 5
A37: 40064472 | B37: PA EDP TWINPCK EUPHO+ HARMONY M1599P10 | C37: 30 | D37: GIT
A38: 40049949 | B38: PA SIGNATURE COLLECTION KIT M899P6 | C38: 10
A39: 40064430 | B39: PA SOAP PURE LXRY 4X125GPO4 M320 P27GCPL | C39: 2 | D39: GIT
A40: 40064428 | B40: PA SOAP PURE LXRY125GB3G1 M240 P27 N | C40: 19 | D40: GIT
A41: 40064558 | B41: PA SOAPGOOD MRNG4X125GPO4M320 P27GCPL | C41: 10 | D41: GIT
C43: =SUM(C34:C42) -> 131
A44: Driver Sign | D44: Loading Total
...

Sheet AHMD-2
I1: 6355.33 | J1: 26094198
I2: 11600.24 | J2: 35395403
A5: GODREJ CONSUMER PRODUCTS LTD
A6: C/O RPM Logistics Pvt Ltd. Add- E - 2 Vadpa Village BHIWANDI-421302
A7: Loading Sheet | C7: GATE NO: | E7: Plan Time: 15:19
A8: Transport Name | B8: Kapoor | C8: 808951625 | E8: Date | F8: 30.10.2026 | G8: Weight | H8: 18MT
A9: Vehicle no | B9: NL01AE2938 | C9: 808951635 | E9: Start Time | G9: Volum | H9: 62000
A10: Destination | B10: AHMD-2 | C10: 808952841 | E10: End Time | G10: Indent
A11: Driver No | B11: R R - 9116911697 | C11: 808952842 | G11: GCPL-C121-O-12964
A12: Code | B12: Description | C12: Del Qty | D12: Priority | E12: MRP | F12: PKD | G12: Load Qty | H12: Remarks
A13: 40043571 | B13: *PA SC CLASSIC 84G M75 P48 | C13: 15 | E13: 15
A14: 40043584 | B14: *PA SC GOOD MORNING 84G M75 P48 | C14: 10 | E14: 10
A15: 40062265 | B15: AER MATIC SPRAY REF CSB 210ML M249P18 NP | C15: 50 | E15: 50
A16: 40060029 | B16: AER MATIC SPRAY REFILL FLG 210ML M249P18 | C16: 35 | E16: 35
A17: 40060034 | B17: AER MATIC SPRY RFILL VVB 210ML M249P18NF | C17: 200 | E17: 200 | I17: 1006210180
A18: 40062345 | B18: AER O CARAMEL LATTE 7.5G M99P60 | C18: 34 | E18: 34 | I18: 5128542
A19: 40041315 | B19: AER O coolaqua 7.5g M99 PO60 | C19: 78 | E19: 78 | I19: 5128541
A20: 40062464 | B20: AER O ORANGE PUNCH 7.5G M99P60 | C20: 27 | E20: 27 | I20: 1006210178
A21: 40062014 | B21: AER PLUG REFILL V BLOOM 25ML 2R M199P36 | C21: 5 | E21: 5
A22: 40064164 | B22: AER PLUG ROSE BLOSSOM COMBI1M+2R M275P24 | C22: 9 | E22: 9
A23: 40050858 | B23: AER PO3 POWERPOCKET ASSORTED M195P36ECOM | C23: 4 | E23: 0
A24: 40063022 | B24: AER PO5 PWRPCKT ASSORTED M350P24 ECOM NF | C24: 65 | E24: 65
A25: 40063752 | B25: AER SPRAY CITRUS BLAST 180ML M99P24 | C25: 41 | E25: 0
A26: 40063753 | B26: AER SPRAY COOLAQUA 180ML M99P24 | C26: 40 | E26: 40
A27: 40063700 | B27: AER SPRAY FOREST FRESH 180ML M99P24 | C27: 12 | E27: 12
A28: 40063699 | B28: AER SPRAY JASMINEDELIGHT 180ML M99P24 | C28: 26 | E28: 26
A29: 40063688 | B29: AER SPRAY LAVENDERBLOOM 180ML M99P24 | C29: 75 | E29: 75
A30: 40063689 | B30: AER SPRAY MYSTIC MUSK 180ML M99P24 | C30: 25 | E30: 25
A31: 40063794 | B31: AER SPRAY SANDAL BLISS 180ML M99P24 | C31: 1 | E31: 1
A32: 40049729 | B32: AER SPRAY VIOLET VALLEY 220ml M99P24 | C32: 17 | E32: 17
... A34: 40065167 | B34: AERPWRPCKT PO3 LMN TAN M195P36 NEW | C34: 1 | E34: 1
A35: 40063581 | B35: CIN COOL 75G PO4 M110 P50 NEWRSTRD | C35: 34 | D35: GIT | E35: 34
A36: 40057928 | B36: CIN COOL BDYWASH BOTTLE 200ML M120P30 | C36: 30 | E36: 30
A37: 40063757 | B37: CIN HEALTH+ 38G NEW M10 P216 RSTRD | C37: 130 | D37: GIT | E37: 130
A38: 40063808 | B38: CIN LIME 100G B4G1 M180P36 GT(ROI)RSTRD | C38: 30 | E38: 0
A39: 40063756 | B39: CIN LIME 38G SING M10 P216 RSTRD | C39: 31 | E39: 31
A40: 40059774 | B40: CIN LIME BDYWASH BOTTLE 750ML M330P12 | C40: 5 | E40: 5
A41: 40049658 | B41: Cin Org Bdywash Bottle 200ml M120 P30 | C41: 5 | E41: 5
A42: 40065039 | B42: CIN ORG100G PO4 M175 P36 NEW MT | C42: 4 | D42: GIT | E42: 4
A43: 40060449 | B43: CIN SANDAL BDYWASH BOTTLE 200ML M120P30 | C43: 5 | E43: 5
...

Sheet Tepla-1
I1: 10974.96 | J1: 37732179
I2: 6959.88 | J2: 25453587
A5: GODREJ CONSUMER PRODUCTS LTD
A6: C/O RPM Logistics Pvt Ltd. Add- E - 2 Vadpa Village BHIWANDI-421302
A7: Loading Sheet | C7: GATE NO: | E7: Plan Time: 15:28
A8: Transport Name | B8: One Point | C8: 808951659 | E8: Date | F8: 30.10.2026 | G8: Weight | H8: 18MT
A9: Vehicle no | B9: HR68C2473 | C9: 808951667 | E9: Start Time | G9: Volum | H9: 63000
A10: Destination | B10: Tepla-1 | C10: 808952833 | E10: End Time | G10: Indent
A11: Driver No | B11: R R - 9729653415 | G11: GCPL-C121-M-12966
A12: Code | B12: Description | C12: Del Qty | D12: Priority | E12: MRP | F12: PKD | G12: Load Qty | H12: Remarks
A13: 40043571 | B13: *PA SC CLASSIC 84G M75 P48 | C13: 75
A14: 40060030 | B14: AER MATIC REFILL ALIVE 225ML M249P18 | C14: 1000
A15: 40060029 | B15: AER MATIC SPRAY REFILL FLG 210ML M249P18 | C15: 81
A16: 40063407 | B16: AERPWRPCKT JASFLORDELI 10G M70P120 | C16: 200 | D16: T T | I16: 1006210173
A17: 40060450 | B17: CIN SANDAL BDYWASH BOTTLE 750ML M330P12 | C17: 150 | I17: 5128540
A18: 40059605 | B18: EZEE 36G SACHET(12UX18N) M10 P216 NEWPCK | C18: 200 | D18: T T | I18: 5128539
A19: 40063612 | B19: KALI MEHENDI 3G X8 SACHETS P45 M120 NFR | C19: 1 | I19: 1006210172
A20: 40062332 | B20: KS10'S SKINFEEL M180 P480 NEWAW | C20: 50
A21: 40062523 | B21: KS10'S STRAWBERRYFLV M100 P480 NEWAW | C21: 200
A22: 40058326 | B22: PA AMAZONWOODS 120ML M225 P48 (8*6)INNER | C22: 80 | D22: CFA
A23: 40060738 | B23: PA ASL GM 50ML (AUTOMIZER) G M135P18 | C23: 48
A24: 40049949 | B24: PA SIGNATURE COLLECTION KIT M899P6 | C24: 250
A25: 40063685 | B25: PROTET GRMFIGHTHW LIM&EUREF650ML M99P18 | C25: 128
